Workbook

Sheet Full Analysis
B1: 9.05 | J1: 11.06 | R1: 11.06
A2: NR Q No. | B2: H | C2: PBL | D2: FBL | E2: PRK | F2: FRK | G2: NA | H2: OG | I2: Total | J2: H | K2: PBL | L2: FBL | M2: PRK | N2: FRK | O2: NA | P2: OG | Q2: Total | R2: H | S2: PBL | T2: FBL | U2: PRK | V2: FRK | W2: NA | X2: OG | Y2: Total
A3: Q1 | B3: 0 | C3: 0 | D3: 0 | E3: 0 | F3: 0 | G3: 0 | H3: 0 | I3: =SUM(B3:H3) -> 0 | J3: 0 | K3: 0 | L3: 0 | M3: 0 | N3: 0 | O3: 0 | P3: 0 | Q3: =SUM(J3:P3) -> 0
A4: Q2 | B4: 0 | C4: 0 | D4: 0 | E4: 0 | F4: 0 | G4: 0 | H4: 0 | I4: =SUM(B4:H4) -> 0 | J4: 0 | K4: 0 | L4: 0 | M4: 0 | N4: 0 | O4: 0 | P4: 0 | Q4: =SUM(J4:P4) -> 0
A5: Q3 | B5: 0 | C5: 0 | D5: 0 | E5: 0 | F5: 0 | G5: 0 | H5: 0 | I5: =SUM(B5:H5) -> 0 | J5: 0 | K5: 0 | L5: 0 | M5: 0 | N5: 0 | O5: 0 | P5: 0 | Q5: =SUM(J5:P5) -> 0
A6: Q4 | B6: 0 | C6: 0 | D6: 0 | E6: 0 | F6: 0 | G6: 0 | H6: 0 | I6: =SUM(B6:H6) -> 0 | J6: 0 | K6: 0 | L6: 0 | M6: 0 | N6: 0 | O6: 0 | P6: 0 | Q6: =SUM(J6:P6) -> 0
A7: Q5 | B7: 0 | C7: 0 | D7: 0 | E7: 0 | F7: 0 | G7: 0 | H7: 0 | I7: =SUM(B7:H7) -> 0 | J7: 0 | K7: 0 | L7: 0 | M7: 0 | N7: 0 | O7: 0 | P7: 0 | Q7: =SUM(J7:P7) -> 0
A8: Q6 | B8: 0 | C8: 0 | D8: 0 | E8: 0 | F8: 0 | G8: 0 | H8: 0 | I8: =SUM(B8:H8) -> 0 | J8: 0 | K8: 0 | L8: 0 | M8: 0 | N8: 0 | O8: 0 | P8: 0 | Q8: =SUM(J8:P8) -> 0
A9: Q7 | B9: 0 | C9: 0 | D9: 0 | E9: 0 | F9: 0 | G9: 0 | H9: 0 | I9: =SUM(B9:H9) -> 0 | J9: 0 | K9: 0 | L9: 0 | M9: 0 | N9: 0 | O9: 0 | P9: 0 | Q9: =SUM(J9:P9) -> 0
A10: Q8 | B10: 0 | C10: 0 | D10: 0 | E10: 0 | F10: 0 | G10: 0 | H10: 0 | I10: =SUM(B10:H10) -> 0 | J10: 0 | K10: 0 | L10: 0 | M10: 0 | N10: 0 | O10: 0 | P10: 0 | Q10: =SUM(J10:P10) -> 0
A11: Q9 | B11: 0 | C11: 0 | D11: 0 | E11: 0 | F11: 0 | G11: 0 | H11: 0 | I11: =SUM(B11:H11) -> 0 | J11: 0 | K11: 0 | L11: 0 | M11: 0 | N11: 0 | O11: 0 | P11: 0 | Q11: =SUM(J11:P11) -> 0
A12: Q10 | B12: 0 | C12: 0 | D12: 0 | E12: 0 | F12: 0 | G12: 0 | H12: 0 | I12: =SUM(B12:H12) -> 0 | J12: 0 | K12: 0 | L12: 0 | M12: 0 | N12: 0 | O12: 0 | P12: 0 | Q12: =SUM(J12:P12) -> 0
A13: Q11 | B13: 0 | C13: 0 | D13: 0 | E13: 0 | F13: 0 | G13: 0 | H13: 0 | I13: =SUM(B13:H13) -> 0 | J13: 0 | K13: 0 | L13: 0 | M13: 0 | N13: 0 | O13: 0 | P13: 0 | Q13: =SUM(J13:P13) -> 0
A14: Q12 | B14: 0 | C14: 0 | D14: 0 | E14: 0 | F14: 0 | G14: 0 | H14: 0 | I14: =SUM(B14:H14) -> 0 | J14: 0 | K14: 0 | L14: 0 | M14: 0 | N14: 0 | O14: 0 | P14: 0 | Q14: =SUM(J14:P14) -> 0
... A42: Q40 | B42: 0 | C42: 0 | D42: 0 | E42: 0 | F42: 0 | G42: 0 | H42: 0 | I42: =SUM(B42:H42) -> 0 | J42: 0 | K42: 0 | L42: 0 | M42: 0 | N42: 0 | O42: 0 | P42: 0 | Q42: =SUM(J42:P42) -> 0

Sheet AR Blocks Analysis - Quadrat-le
B1: 09.05 | J1: 13.06 | R1: 03.08 | Z1: 27.08
A2: Quadrat | B2: Coral Count | C2: Healthy Count | D2: H | E2: PBL | F2: FBL | G2: PRK | H2: FRK | I2: TOTAL | J2: Coral Count | K2: Healthy Count | L2: H | M2: PBL | N2: FBL | O2: PRK | P2: FRK | Q2: TOTAL | R2: Coral Count | S2: Healthy Count | T2: H | U2: PBL | V2: FBL | W2: PRK | X2: FRK | Y2: TOTAL | Z2: Coral Count | AA2: Healthy Count | AB2: H | AC2: PBL | AD2: FBL | AE2: PRK | AF2: FRK | AG2: DIS | AH2: TOTAL
A3: Block1_Q1 | B3: =COUNTIFS('Mango Blocks - 09.05 - LONG'!$E:$E,"<>NA",'Mango Blocks - 09.05 - LONG'!$E:$E,"<>OG",'Mango Blocks - 09.05 - LONG'!$E:$E,"<>-",'Mango Blocks - 09.05 - LONG'!$C:$C,$A3) -> 0 | C3: =IF($B3=0,"NA",COUNTIFS('Mango Blocks - 09.05 - LONG'!$E:$E,"H",'Mango Blocks - 09.05 - LONG'!$C:$C,$A3)) -> NA | D3: =IF($B3=0,"NA",COUNTIFS('Mango Blocks - 09.05 - LONG'!$E:$E,"H",'Mango Blocks - 09.05 - LONG'!$C:$C,$A3)/B3) -> NA | E3: =IF($B3=0,"NA",COUNTIFS('Mango Blocks - 09.05 - LONG'!$E:$E,"PBL",'Mango Blocks - 09.05 - LONG'!$C:$C,$A3)/B3) -> NA | F3: =IF($B3=0,"NA",COUNTIFS('Mango Blocks - 09.05 - LONG'!$E:$E,"FBL",'Mango Blocks - 09.05 - LONG'!$C:$C,$A3)/B3) -> NA | G3: =IF($B3=0,"NA",COUNTIFS('Mango Blocks - 09.05 - LONG'!$E:$E,"PRK",'Mango Blocks - 09.05 - LONG'!$C:$C,$A3)/B3) -> NA | H3: =IF($B3=0,"NA",COUNTIFS('Mango Blocks - 09.05 - LONG'!$E:$E,"FRK",'Mango Blocks - 09.05 - LONG'!$C:$C,$A3)/B3) -> NA | I3: =IF(C3="NA","NA",SUM(D3:H3)) -> NA | J3: =COUNTIFS('Mango Blocks - 13.06 - LONG'!$E:$E,"<>NA",'Mango Blocks - 13.06 - LONG'!$E:$E,"<>OG",'Mango Blocks - 13.06 - LONG'!$E:$E,"<>-",'Mango Blocks - 13.06 - LONG'!$C:$C,$A3) -> 16 | K3: =IF(J3=0,"NA",COUNTIFS('Mango Blocks - 13.06 - LONG'!$E:$E,"H",'Mango Blocks - 13.06 - LONG'!$C:$C,$A3)) -> 2 | L3: =IF(J3=0,"NA",COUNTIFS('Mango Blocks - 13.06 - LONG'!$E:$E,"H",'Mango Blocks - 13.06 - LONG'!$C:$C,$A3)/J3) -> 0.125 | M3: =IF(J3=0,"NA",COUNTIFS('Mango Blocks - 13.06 - LONG'!$E:$E,"PBL",'Mango Blocks - 13.06 - LONG'!$C:$C,$A3)/J3) -> 0 | N3: =IF(J3=0,"NA",COUNTIFS('Mango Blocks - 13.06 - LONG'!$E:$E,"FBL",'Mango Blocks - 13.06 - LONG'!$C:$C,$A3)/J3) -> 0 | O3: =IF(J3=0,"NA",COUNTIFS('Mango Blocks - 13.06 - LONG'!$E:$E,"PRK",'Mango Blocks - 13.06 - LONG'!$C:$C,$A3)/J3) -> 0 | P3: =IF(J3=0,"NA",COUNTIFS('Mango Blocks - 13.06 - LONG'!$E:$E,"FRK",'Mango Blocks - 13.06 - LONG'!$C:$C,$A3)/J3) -> 0.875 | Q3: =IF(K3="NA","NA",SUM(L3:P3)) -> 1 | R3: =COUNTIFS('Mango Blocks - 03.08 - LONG'!$E:$E,"<>NA",'Mango Blocks - 03.08 - LONG'!$E:$E,"<>OG",'Mango Blocks - 03.08 - LONG'!$E:$E,"<>-",'Mango Blocks - 03.08 - LONG'!$C:$C,$A3) -> 0 | S3: =IF(R3=0,"NA",COUNTIFS('Mango Blocks - 03.08 - LONG'!$E:$E,"H",'Mango Blocks - 03.08 - LONG'!$C:$C,$A3)) -> NA | T3: =IF(R3=0,"NA",COUNTIFS('Mango Blocks - 03.08 - LONG'!$E:$E,T$2,'Mango Blocks - 03.08 - LONG'!$C:$C,$A3)/R3) -> NA | U3: =IF(R3=0,"NA",COUNTIFS('Mango Blocks - 03.08 - LONG'!$E:$E,U$2,'Mango Blocks - 03.08 - LONG'!$C:$C,$A3)/R3) -> NA | V3: =IF(R3=0,"NA",COUNTIFS('Mango Blocks - 03.08 - LONG'!$E:$E,V$2,'Mango Blocks - 03.08 - LONG'!$C:$C,$A3)/R3) -> NA | W3: =IF(R3=0,"NA",COUNTIFS('Mango Blocks - 03.08 - LONG'!$E:$E,W$2,'Mango Blocks - 03.08 - LONG'!$C:$C,$A3)/R3) -> NA | X3: =IF(R3=0,"NA",COUNTIFS('Mango Blocks - 03.08 - LONG'!$E:$E,X$2,'Mango Blocks - 03.08 - LONG'!$C:$C,$A3)/R3) -> NA | Y3: =IF(S3="NA","NA",SUM(T3:X3)) -> NA | Z3: =COUNTIFS('Mango Blocks - 27.08 - LONG'!$E:$E,"<>NA",'Mango Blocks - 27.08 - LONG'!$E:$E,"<>OG",'Mango Blocks - 27.08 - LONG'!$E:$E,"<>-",'Mango Blocks - 27.08 - LONG'!$C:$C,$A3) -> 0 | AA3: =IF(Z3=0,"NA",COUNTIFS('Mango Blocks - 27.08 - LONG'!$E:$E,"H",'Mango Blocks - 27.08 - LONG'!$C:$C,$A3)) -> NA | AB3: =IF(Z3=0,"NA",COUNTIFS('Mango Blocks - 27.08 - LONG'!$E:$E,AB$2,'Mango Blocks - 27.08 - LONG'!$C:$C,$A3)/Z3) -> NA | AC3: =IF(Z3=0,"NA",COUNTIFS('Mango Blocks - 27.08 - LONG'!$E:$E,AC$2,'Mango Blocks - 27.08 - LONG'!$C:$C,$A3)/Z3) -> NA | AD3: =IF(Z3=0,"NA",COUNTIFS('Mango Blocks - 27.08 - LONG'!$E:$E,AD$2,'Mango Blocks - 27.08 - LONG'!$C:$C,$A3)/Z3) -> NA | AE3: =IF(Z3=0,"NA",COUNTIFS('Mango Blocks - 27.08 - LONG'!$E:$E,AE$2,'Mango Blocks - 27.08 - LONG'!$C:$C,$A3)/Z3) -> NA | AF3: =IF(Z3=0,"NA",COUNTIFS('Mango Blocks - 27.08 - LONG'!$E:$E,AF$2,'Mango Blocks - 27.08 - LONG'!$C:$C,$A3)/Z3) -> NA | AG3: =IF(Z3=0,"NA",COUNTIFS('Mango Blocks - 27.08 - LONG'!$E:$E,AG$2,'Mango Blocks - 27.08 - LONG'!$C:$C,$A3)/Z3) -> NA | AH3: =IF(AA3="NA","NA",SUM(AB3:AF3)) -> NA
A4: Block1_Q2 | B4: =COUNTIFS('Mango Blocks - 09.05 - LONG'!$E:$E,"<>NA",'Mango Blocks - 09.05 - LONG'!$E:$E,"<>OG",'Mango Blocks - 09.05 - LONG'!$E:$E,"<>-",'Mango Blocks - 09.05 - LONG'!$C:$C,$A4) -> 17 | C4: =IF($B4=0,"NA",COUNTIFS('Mango Blocks - 09.05 - LONG'!$E:$E,"H",'Mango Blocks - 09.05 - LONG'!$C:$C,$A4)) -> 0 | D4: =IF($B4=0,"NA",COUNTIFS('Mango Blocks - 09.05 - LONG'!$E:$E,"H",'Mango Blocks - 09.05 - LONG'!$C:$C,$A4)/B4) -> 0 | E4: =IF($B4=0,"NA",COUNTIFS('Mango Blocks - 09.05 - LONG'!$E:$E,"PBL",'Mango Blocks - 09.05 - LONG'!$C:$C,$A4)/B4) -> 0.41176471 | F4: =IF($B4=0,"NA",COUNTIFS('Mango Blocks - 09.05 - LONG'!$E:$E,"FBL",'Mango Blocks - 09.05 - LONG'!$C:$C,$A4)/B4) -> 0 | G4: =IF($B4=0,"NA",COUNTIFS('Mango Blocks - 09.05 - LONG'!$E:$E,"PRK",'Mango Blocks - 09.05 - LONG'!$C:$C,$A4)/B4) -> 0 | H4: =IF($B4=0,"NA",COUNTIFS('Mango Blocks - 09.05 - LONG'!$E:$E,"FRK",'Mango Blocks - 09.05 - LONG'!$C:$C,$A4)/B4) -> 0.58823529 | I4: =IF(C4="NA","NA",SUM(D4:H4)) -> 1 | J4: =COUNTIFS('Mango Blocks - 13.06 - LONG'!$E:$E,"<>NA",'Mango Blocks - 13.06 - LONG'!$E:$E,"<>OG",'Mango Blocks - 13.06 - LONG'!$E:$E,"<>-",'Mango Blocks - 13.06 - LONG'!$C:$C,$A4) -> 0 | K4: =IF(J4=0,"NA",COUNTIFS('Mango Blocks - 13.06 - LONG'!$E:$E,"H",'Mango Blocks - 13.06 - LONG'!$C:$C,$A4)) -> NA | L4: =IF(J4=0,"NA",COUNTIFS('Mango Blocks - 13.06 - LONG'!$E:$E,"H",'Mango Blocks - 13.06 - LONG'!$C:$C,$A4)/J4) -> NA | M4: =IF(J4=0,"NA",COUNTIFS('Mango Blocks - 13.06 - LONG'!$E:$E,"PBL",'Mango Blocks - 13.06 - LONG'!$C:$C,$A4)/J4) -> NA | N4: =IF(J4=0,"NA",COUNTIFS('Mango Blocks - 13.06 - LONG'!$E:$E,"FBL",'Mango Blocks - 13.06 - LONG'!$C:$C,$A4)/J4) -> NA | O4: =IF(J4=0,"NA",COUNTIFS('Mango Blocks - 13.06 - LONG'!$E:$E,"PRK",'Mango Blocks - 13.06 - LONG'!$C:$C,$A4)/J4) -> NA | P4: =IF(J4=0,"NA",COUNTIFS('Mango Blocks - 13.06 - LONG'!$E:$E,"FRK",'Mango Blocks - 13.06 - LONG'!$C:$C,$A4)/J4) -> NA | Q4: =IF(K4="NA","NA",SUM(L4:P4)) -> NA | R4: =COUNTIFS('Mango Blocks - 03.08 - LONG'!$E:$E,"<>NA",'Mango Blocks - 03.08 - LONG'!$E:$E,"<>OG",'Mango Blocks - 03.08 - LONG'!$E:$E,"<>-",'Mango Blocks - 03.08 - LONG'!$C:$C,$A4) -> 0 | S4: =IF(R4=0,"NA",COUNTIFS('Mango Blocks - 03.08 - LONG'!$E:$E,"H",'Mango Blocks - 03.08 - LONG'!$C:$C,$A4)) -> NA | T4: =IF(R4=0,"NA",COUNTIFS('Mango Blocks - 03.08 - LONG'!$E:$E,T$2,'Mango Blocks - 03.08 - LONG'!$C:$C,$A4)/R4) -> NA | U4: =IF(R4=0,"NA",COUNTIFS('Mango Blocks - 03.08 - LONG'!$E:$E,U$2,'Mango Blocks - 03.08 - LONG'!$C:$C,$A4)/R4) -> NA | V4: =IF(R4=0,"NA",COUNTIFS('Mango Blocks - 03.08 - LONG'!$E:$E,V$2,'Mango Blocks - 03.08 - LONG'!$C:$C,$A4)/R4) -> NA | W4: =IF(R4=0,"NA",COUNTIFS('Mango Blocks - 03.08 - LONG'!$E:$E,W$2,'Mango Blocks - 03.08 - LONG'!$C:$C,$A4)/R4) -> NA | X4: =IF(R4=0,"NA",COUNTIFS('Mango Blocks - 03.08 - LONG'!$E:$E,X$2,'Mango Blocks - 03.08 - LONG'!$C:$C,$A4)/R4) -> NA | Y4: =IF(S4="NA","NA",SUM(T4:X4)) -> NA | Z4: =COUNTIFS('Mango Blocks - 27.08 - LONG'!$E:$E,"<>NA",'Mango Blocks - 27.08 - LONG'!$E:$E,"<>OG",'Mango Blocks - 27.08 - LONG'!$E:$E,"<>-",'Mango Blocks - 27.08 - LONG'!$C:$C,$A4) -> 19 | AA4: =IF(Z4=0,"NA",COUNTIFS('Mango Blocks - 27.08 - LONG'!$E:$E,"H",'Mango Blocks - 27.08 - LONG'!$C:$C,$A4)) -> 0 | AB4: =IF(Z4=0,"NA",COUNTIFS('Mango Blocks - 27.08 - LONG'!$E:$E,AB$2,'Mango Blocks - 27.08 - LONG'!$C:$C,$A4)/Z4) -> 0 | AC4: =IF(Z4=0,"NA",COUNTIFS('Mango Blocks - 27.08 - LONG'!$E:$E,AC$2,'Mango Blocks - 27.08 - LONG'!$C:$C,$A4)/Z4) -> 0.57894737 | AD4: =IF(Z4=0,"NA",COUNTIFS('Mango Blocks - 27.08 - LONG'!$E:$E,AD$2,'Mango Blocks - 27.08 - LONG'!$C:$C,$A4)/Z4) -> 0.052631579 | AE4: =IF(Z4=0,"NA",COUNTIFS('Mango Blocks - 27.08 - LONG'!$E:$E,AE$2,'Mango Blocks - 27.08 - LONG'!$C:$C,$A4)/Z4) -> 0.052631579 | AF4: =IF(Z4=0,"NA",COUNTIFS('Mango Blocks - 27.08 - LONG'!$E:$E,AF$2,'Mango Blocks - 27.08 - LONG'!$C:$C,$A4)/Z4) -> 0.31578947 | AG4: =IF(Z4=0,"NA",COUNTIFS('Mango Blocks - 27.08 - LONG'!$E:$E,AG$2,'Mango Blocks - 27.08 - LONG'!$C:$C,$A4)/Z4) -> 0 | AH4: =IF(AA4="NA","NA",SUM(AB4:AF4)) -> 1
A5: Block1_Q3 | B5: =COUNTIFS('Mango Blocks - 09.05 - LONG'!$E:$E,"<>NA",'Mango Blocks - 09.05 - LONG'!$E:$E,"<>OG",'Mango Blocks - 09.05 - LONG'!$E:$E,"<>-",'Mango Blocks - 09.05 - LONG'!$C:$C,$A5) -> 19 | C5: =IF($B5=0,"NA",COUNTIFS('Mango Blocks - 09.05 - LONG'!$E:$E,"H",'Mango Blocks - 09.05 - LONG'!$C:$C,$A5)) -> 2 | D5: =IF($B5=0,"NA",COUNTIFS('Mango Blocks - 09.05 - LONG'!$E:$E,"H",'Mango Blocks - 09.05 - LONG'!$C:$C,$A5)/B5) -> 0.10526316 | E5: =IF($B5=0,"NA",COUNTIFS('Mango Blocks - 09.05 - LONG'!$E:$E,"PBL",'Mango Blocks - 09.05 - LONG'!$C:$C,$A5)/B5) -> 0.89473684 | F5: =IF($B5=0,"NA",COUNTIFS('Mango Blocks - 09.05 - LONG'!$E:$E,"FBL",'Mango Blocks - 09.05 - LONG'!$C:$C,$A5)/B5) -> 0 | G5: =IF($B5=0,"NA",COUNTIFS('Mango Blocks - 09.05 - LONG'!$E:$E,"PRK",'Mango Blocks - 09.05 - LONG'!$C:$C,$A5)/B5) -> 0 | H5: =IF($B5=0,"NA",COUNTIFS('Mango Blocks - 09.05 - LONG'!$E:$E,"FRK",'Mango Blocks - 09.05 - LONG'!$C:$C,$A5)/B5) -> 0 | I5: =IF(C5="NA","NA",SUM(D5:H5)) -> 1 | J5: =COUNTIFS('Mango Blocks - 13.06 - LONG'!$E:$E,"<>NA",'Mango Blocks - 13.06 - LONG'!$E:$E,"<>OG",'Mango Blocks - 13.06 - LONG'!$E:$E,"<>-",'Mango Blocks - 13.06 - LONG'!$C:$C,$A5) -> 20 | K5: =IF(J5=0,"NA",COUNTIFS('Mango Blocks - 13.06 - LONG'!$E:$E,"H",'Mango Blocks - 13.06 - LONG'!$C:$C,$A5)) -> 0 | L5: =IF(J5=0,"NA",COUNTIFS('Mango Blocks - 13.06 - LONG'!$E:$E,"H",'Mango Blocks - 13.06 - LONG'!$C:$C,$A5)/J5) -> 0 | M5: =IF(J5=0,"NA",COUNTIFS('Mango Blocks - 13.06 - LONG'!$E:$E,"PBL",'Mango Blocks - 13.06 - LONG'!$C:$C,$A5)/J5) -> 0.85 | N5: =IF(J5=0,"NA",COUNTIFS('Mango Blocks - 13.06 - LONG'!$E:$E,"FBL",'Mango Blocks - 13.06 - LONG'!$C:$C,$A5)/J5) -> 0.05 | O5: =IF(J5=0,"NA",COUNTIFS('Mango Blocks - 13.06 - LONG'!$E:$E,"PRK",'Mango Blocks - 13.06 - LONG'!$C:$C,$A5)/J5) -> 0.1 | P5: =IF(J5=0,"NA",COUNTIFS('Mango Blocks - 13.06 - LONG'!$E:$E,"FRK",'Mango Blocks - 13.06 - LONG'!$C:$C,$A5)/J5) -> 0 | Q5: =IF(K5="NA","NA",SUM(L5:P5)) -> 1 | R5: =COUNTIFS('Mango Blocks - 03.08 - LONG'!$E:$E,"<>NA",'Mango Blocks - 03.08 - LONG'!$E:$E,"<>OG",'Mango Blocks - 03.08 - LONG'!$E:$E,"<>-",'Mango Blocks - 03.08 - LONG'!$C:$C,$A5) -> 17 | S5: =IF(R5=0,"NA",COUNTIFS('Mango Blocks - 03.08 - LONG'!$E:$E,"H",'Mango Blocks - 03.08 - LONG'!$C:$C,$A5)) -> 0 | T5: =IF(R5=0,"NA",COUNTIFS('Mango Blocks - 03.08 - LONG'!$E:$E,T$2,'Mango Blocks - 03.08 - LONG'!$C:$C,$A5)/R5) -> 0 | U5: =IF(R5=0,"NA",COUNTIFS('Mango Blocks - 03.08 - LONG'!$E:$E,U$2,'Mango Blocks - 03.08 - LONG'!$C:$C,$A5)/R5) -> 0.52941176 | V5: =IF(R5=0,"NA",COUNTIFS('Mango Blocks - 03.08 - LONG'!$E:$E,V$2,'Mango Blocks - 03.08 - LONG'!$C:$C,$A5)/R5) -> 0 | W5: =IF(R5=0,"NA",COUNTIFS('Mango Blocks - 03.08 - LONG'!$E:$E,W$2,'Mango Blocks - 03.08 - LONG'!$C:$C,$A5)/R5) -> 0.058823529 | X5: =IF(R5=0,"NA",COUNTIFS('Mango Blocks - 03.08 - LONG'!$E:$E,X$2,'Mango Blocks - 03.08 - LONG'!$C:$C,$A5)/R5) -> 0.41176471 | Y5: =IF(S5="NA","NA",SUM(T5:X5)) -> 1 | Z5: =COUNTIFS('Mango Blocks - 27.08 - LONG'!$E:$E,"<>NA",'Mango Blocks - 27.08 - LONG'!$E:$E,"<>OG",'Mango Blocks - 27.08 - LONG'!$E:$E,"<>-",'Mango Blocks - 27.08 - LONG'!$C:$C,$A5) -> 22 | AA5: =IF(Z5=0,"NA",COUNTIFS('Mango Blocks - 27.08 - LONG'!$E:$E,"H",'Mango Blocks - 27.08 - LONG'!$C:$C,$A5)) -> 21 | AB5: =IF(Z5=0,"NA",COUNTIFS('Mango Blocks - 27.08 - LONG'!$E:$E,AB$2,'Mango Blocks - 27.08 - LONG'!$C:$C,$A5)/Z5) -> 0.95454545 | AC5: =IF(Z5=0,"NA",COUNTIFS('Mango Blocks - 27.08 - LONG'!$E:$E,AC$2,'Mango Blocks - 27.08 - LONG'!$C:$C,$A5)/Z5) -> 0.045454545 | AD5: =IF(Z5=0,"NA",COUNTIFS('Mango Blocks - 27.08 - LONG'!$E:$E,AD$2,'Mango Blocks - 27.08 - LONG'!$C:$C,$A5)/Z5) -> 0 | AE5: =IF(Z5=0,"NA",COUNTIFS('Mango Blocks - 27.08 - LONG'!$E:$E,AE$2,'Mango Blocks - 27.08 - LONG'!$C:$C,$A5)/Z5) -> 0 | AF5: =IF(Z5=0,"NA",COUNTIFS('Mango Blocks - 27.08 - LONG'!$E:$E,AF$2,'Mango Blocks - 27.08 - LONG'!$C:$C,$A5)/Z5) -> 0 | AG5: =IF(Z5=0,"NA",COUNTIFS('Mango Blocks - 27.08 - LONG'!$E:$E,AG$2,'Mango Blocks - 27.08 - LONG'!$C:$C,$A5)/Z5) -> 0 | AH5: =IF(AA5="NA","NA",SUM(AB5:AF5)) -> 1
A6: Block1_Q4 | B6: =COUNTIFS('Mango Blocks - 09.05 - LONG'!$E:$E,"<>NA",'Mango Blocks - 09.05 - LONG'!$E:$E,"<>OG",'Mango Blocks - 09.05 - LONG'!$E:$E,"<>-",'Mango Blocks - 09.05 - LONG'!$C:$C,$A6) -> 2 | C6: =IF($B6=0,"NA",COUNTIFS('Mango Blocks - 09.05 - LONG'!$E:$E,"H",'Mango Blocks - 09.05 - LONG'!$C:$C,$A6)) -> 2 | D6: =IF($B6=0,"NA",COUNTIFS('Mango Blocks - 09.05 - LONG'!$E:$E,"H",'Mango Blocks - 09.05 - LONG'!$C:$C,$A6)/B6) -> 1 | E6: =IF($B6=0,"NA",COUNTIFS('Mango Blocks - 09.05 - LONG'!$E:$E,"PBL",'Mango Blocks - 09.05 - LONG'!$C:$C,$A6)/B6) -> 0 | F6: =IF($B6=0,"NA",COUNTIFS('Mango Blocks - 09.05 - LONG'!$E:$E,"FBL",'Mango Blocks - 09.05 - LONG'!$C:$C,$A6)/B6) -> 0 | G6: =IF($B6=0,"NA",COUNTIFS('Mango Blocks - 09.05 - LONG'!$E:$E,"PRK",'Mango Blocks - 09.05 - LONG'!$C:$C,$A6)/B6) -> 0 | H6: =IF($B6=0,"NA",COUNTIFS('Mango Blocks - 09.05 - LONG'!$E:$E,"FRK",'Mango Blocks - 09.05 - LONG'!$C:$C,$A6)/B6) -> 0 | I6: =IF(C6="NA","NA",SUM(D6:H6)) -> 1 | J6: =COUNTIFS('Mango Blocks - 13.06 - LONG'!$E:$E,"<>NA",'Mango Blocks - 13.06 - LONG'!$E:$E,"<>OG",'Mango Blocks - 13.06 - LONG'!$E:$E,"<>-",'Mango Blocks - 13.06 - LONG'!$C:$C,$A6) -> 4 | K6: =IF(J6=0,"NA",COUNTIFS('Mango Blocks - 13.06 - LONG'!$E:$E,"H",'Mango Blocks - 13.06 - LONG'!$C:$C,$A6)) -> 0 | L6: =IF(J6=0,"NA",COUNTIFS('Mango Blocks - 13.06 - LONG'!$E:$E,"H",'Mango Blocks - 13.06 - LONG'!$C:$C,$A6)/J6) -> 0 | M6: =IF(J6=0,"NA",COUNTIFS('Mango Blocks - 13.06 - LONG'!$E:$E,"PBL",'Mango Blocks - 13.06 - LONG'!$C:$C,$A6)/J6) -> 0.5 | N6: =IF(J6=0,"NA",COUNTIFS('Mango Blocks - 13.06 - LONG'!$E:$E,"FBL",'Mango Blocks - 13.06 - LONG'!$C:$C,$A6)/J6) -> 0.5 | O6: =IF(J6=0,"NA",COUNTIFS('Mango Blocks - 13.06 - LONG'!$E:$E,"PRK",'Mango Blocks - 13.06 - LONG'!$C:$C,$A6)/J6) -> 0 | P6: =IF(J6=0,"NA",COUNTIFS('Mango Blocks - 13.06 - LONG'!$E:$E,"FRK",'Mango Blocks - 13.06 - LONG'!$C:$C,$A6)/J6) -> 0 | Q6: =IF(K6="NA","NA",SUM(L6:P6)) -> 1 | R6: =COUNTIFS('Mango Blocks - 03.08 - LONG'!$E:$E,"<>NA",'Mango Blocks - 03.08 - LONG'!$E:$E,"<>OG",'Mango Blocks - 03.08 - LONG'!$E:$E,"<>-",'Mango Blocks - 03.08 - LONG'!$C:$C,$A6) -> 34 | S6: =IF(R6=0,"NA",COUNTIFS('Mango Blocks - 03.08 - LONG'!$E:$E,"H",'Mango Blocks - 03.08 - LONG'!$C:$C,$A6)) -> 31 | T6: =IF(R6=0,"NA",COUNTIFS('Mango Blocks - 03.08 - LONG'!$E:$E,T$2,'Mango Blocks - 03.08 - LONG'!$C:$C,$A6)/R6) -> 0.91176471 | U6: =IF(R6=0,"NA",COUNTIFS('Mango Blocks - 03.08 - LONG'!$E:$E,U$2,'Mango Blocks - 03.08 - LONG'!$C:$C,$A6)/R6) -> 0.088235294 | V6: =IF(R6=0,"NA",COUNTIFS('Mango Blocks - 03.08 - LONG'!$E:$E,V$2,'Mango Blocks - 03.08 - LONG'!$C:$C,$A6)/R6) -> 0 | W6: =IF(R6=0,"NA",COUNTIFS('Mango Blocks - 03.08 - LONG'!$E:$E,W$2,'Mango Blocks - 03.08 - LONG'!$C:$C,$A6)/R6) -> 0 | X6: =IF(R6=0,"NA",COUNTIFS('Mango Blocks - 03.08 - LONG'!$E:$E,X$2,'Mango Blocks - 03.08 - LONG'!$C:$C,$A6)/R6) -> 0 | Y6: =IF(S6="NA","NA",SUM(T6:X6)) -> 1 | Z6: =COUNTIFS('Mango Blocks - 27.08 - LONG'!$E:$E,"<>NA",'Mango Blocks - 27.08 - LONG'!$E:$E,"<>OG",'Mango Blocks - 27.08 - LONG'!$E:$E,"<>-",'Mango Blocks - 27.08 - LONG'!$C:$C,$A6) -> 3 | AA6: =IF(Z6=0,"NA",COUNTIFS('Mango Blocks - 27.08 - LONG'!$E:$E,"H",'Mango Blocks - 27.08 - LONG'!$C:$C,$A6)) -> 3 | AB6: =IF(Z6=0,"NA",COUNTIFS('Mango Blocks - 27.08 - LONG'!$E:$E,AB$2,'Mango Blocks - 27.08 - LONG'!$C:$C,$A6)/Z6) -> 1 | AC6: =IF(Z6=0,"NA",COUNTIFS('Mango Blocks - 27.08 - LONG'!$E:$E,AC$2,'Mango Blocks - 27.08 - LONG'!$C:$C,$A6)/Z6) -> 0 | AD6: =IF(Z6=0,"NA",COUNTIFS('Mango Blocks - 27.08 - LONG'!$E:$E,AD$2,'Mango Blocks - 27.08 - LONG'!$C:$C,$A6)/Z6) -> 0 | AE6: =IF(Z6=0,"NA",COUNTIFS('Mango Blocks - 27.08 - LONG'!$E:$E,AE$2,'Mango Blocks - 27.08 - LONG'!$C:$C,$A6)/Z6) -> 0 | AF6: =IF(Z6=0,"NA",COUNTIFS('Mango Blocks - 27.08 - LONG'!$E:$E,AF$2,'Mango Blocks - 27.08 - LONG'!$C:$C,$A6)/Z6) -> 0 | AG6: =IF(Z6=0,"NA",COUNTIFS('Mango Blocks - 27.08 - LONG'!$E:$E,AG$2,'Mango Blocks - 27.08 - LONG'!$C:$C,$A6)/Z6) -> 0 | AH6: =IF(AA6="NA","NA",SUM(AB6:AF6)) -> 1
A7: Block1_Q5 | B7: =COUNTIFS('Mango Blocks - 09.05 - LONG'!$E:$E,"<>NA",'Mango Blocks - 09.05 - LONG'!$E:$E,"<>OG",'Mango Blocks - 09.05 - LONG'!$E:$E,"<>-",'Mango Blocks - 09.05 - LONG'!$C:$C,$A7) -> 12 | C7: =IF($B7=0,"NA",COUNTIFS('Mango Blocks - 09.05 - LONG'!$E:$E,"H",'Mango Blocks - 09.05 - LONG'!$C:$C,$A7)) -> 1 | D7: =IF($B7=0,"NA",COUNTIFS('Mango Blocks - 09.05 - LONG'!$E:$E,"H",'Mango Blocks - 09.05 - LONG'!$C:$C,$A7)/B7) -> 0.083333333 | E7: =IF($B7=0,"NA",COUNTIFS('Mango Blocks - 09.05 - LONG'!$E:$E,"PBL",'Mango Blocks - 09.05 - LONG'!$C:$C,$A7)/B7) -> 0.66666667 | F7: =IF($B7=0,"NA",COUNTIFS('Mango Blocks - 09.05 - LONG'!$E:$E,"FBL",'Mango Blocks - 09.05 - LONG'!$C:$C,$A7)/B7) -> 0 | G7: =IF($B7=0,"NA",COUNTIFS('Mango Blocks - 09.05 - LONG'!$E:$E,"PRK",'Mango Blocks - 09.05 - LONG'!$C:$C,$A7)/B7) -> 0.25 | H7: =IF($B7=0,"NA",COUNTIFS('Mango Blocks - 09.05 - LONG'!$E:$E,"FRK",'Mango Blocks - 09.05 - LONG'!$C:$C,$A7)/B7) -> 0 | I7: =IF(C7="NA","NA",SUM(D7:H7)) -> 1 | J7: =COUNTIFS('Mango Blocks - 13.06 - LONG'!$E:$E,"<>NA",'Mango Blocks - 13.06 - LONG'!$E:$E,"<>OG",'Mango Blocks - 13.06 - LONG'!$E:$E,"<>-",'Mango Blocks - 13.06 - LONG'!$C:$C,$A7) -> 0 | K7: =IF(J7=0,"NA",COUNTIFS('Mango Blocks - 13.06 - LONG'!$E:$E,"H",'Mango Blocks - 13.06 - LONG'!$C:$C,$A7)) -> NA | L7: =IF(J7=0,"NA",COUNTIFS('Mango Blocks - 13.06 - LONG'!$E:$E,"H",'Mango Blocks - 13.06 - LONG'!$C:$C,$A7)/J7) -> NA | M7: =IF(J7=0,"NA",COUNTIFS('Mango Blocks - 13.06 - LONG'!$E:$E,"PBL",'Mango Blocks - 13.06 - LONG'!$C:$C,$A7)/J7) -> NA | N7: =IF(J7=0,"NA",COUNTIFS('Mango Blocks - 13.06 - LONG'!$E:$E,"FBL",'Mango Blocks - 13.06 - LONG'!$C:$C,$A7)/J7) -> NA | O7: =IF(J7=0,"NA",COUNTIFS('Mango Blocks - 13.06 - LONG'!$E:$E,"PRK",'Mango Blocks - 13.06 - LONG'!$C:$C,$A7)/J7) -> NA | P7: =IF(J7=0,"NA",COUNTIFS('Mango Blocks - 13.06 - LONG'!$E:$E,"FRK",'Mango Blocks - 13.06 - LONG'!$C:$C,$A7)/J7) -> NA | Q7: =IF(K7="NA","NA",SUM(L7:P7)) -> NA | R7: =COUNTIFS('Mango Blocks - 03.08 - LONG'!$E:$E,"<>NA",'Mango Blocks - 03.08 - LONG'!$E:$E,"<>OG",'Mango Blocks - 03.08 - LONG'!$E:$E,"<>-",'Mango Blocks - 03.08 - LONG'!$C:$C,$A7) -> 4 | S7: =IF(R7=0,"NA",COUNTIFS('Mango Blocks - 03.08 - LONG'!$E:$E,"H",'Mango Blocks - 03.08 - LONG'!$C:$C,$A7)) -> 3 | T7: =IF(R7=0,"NA",COUNTIFS('Mango Blocks - 03.08 - LONG'!$E:$E,T$2,'Mango Blocks - 03.08 - LONG'!$C:$C,$A7)/R7) -> 0.75 | U7: =IF(R7=0,"NA",COUNTIFS('Mango Blocks - 03.08 - LONG'!$E:$E,U$2,'Mango Blocks - 03.08 - LONG'!$C:$C,$A7)/R7) -> 0.25 | V7: =IF(R7=0,"NA",COUNTIFS('Mango Blocks - 03.08 - LONG'!$E:$E,V$2,'Mango Blocks - 03.08 - LONG'!$C:$C,$A7)/R7) -> 0 | W7: =IF(R7=0,"NA",COUNTIFS('Mango Blocks - 03.08 - LONG'!$E:$E,W$2,'Mango Blocks - 03.08 - LONG'!$C:$C,$A7)/R7) -> 0 | X7: =IF(R7=0,"NA",COUNTIFS('Mango Blocks - 03.08 - LONG'!$E:$E,X$2,'Mango Blocks - 03.08 - LONG'!$C:$C,$A7)/R7) -> 0 | Y7: =IF(S7="NA","NA",SUM(T7:X7)) -> 1 | Z7: =COUNTIFS('Mango Blocks - 27.08 - LONG'!$E:$E,"<>NA",'Mango Blocks - 27.08 - LONG'!$E:$E,"<>OG",'Mango Blocks - 27.08 - LONG'!$E:$E,"<>-",'Mango Blocks - 27.08 - LONG'!$C:$C,$A7) -> 7 | AA7: =IF(Z7=0,"NA",COUNTIFS('Mango Blocks - 27.08 - LONG'!$E:$E,"H",'Mango Blocks - 27.08 - LONG'!$C:$C,$A7)) -> 0 | AB7: =IF(Z7=0,"NA",COUNTIFS('Mango Blocks - 27.08 - LONG'!$E:$E,AB$2,'Mango Blocks - 27.08 - LONG'!$C:$C,$A7)/Z7) -> 0 | AC7: =IF(Z7=0,"NA",COUNTIFS('Mango Blocks - 27.08 - LONG'!$E:$E,AC$2,'Mango Blocks - 27.08 - LONG'!$C:$C,$A7)/Z7) -> 1 | AD7: =IF(Z7=0,"NA",COUNTIFS('Mango Blocks - 27.08 - LONG'!$E:$E,AD$2,'Mango Blocks - 27.08 - LONG'!$C:$C,$A7)/Z7) -> 0 | AE7: =IF(Z7=0,"NA",COUNTIFS('Mango Blocks - 27.08 - LONG'!$E:$E,AE$2,'Mango Blocks - 27.08 - LONG'!$C:$C,$A7)/Z7) -> 0 | AF7: =IF(Z7=0,"NA",COUNTIFS('Mango Blocks - 27.08 - LONG'!$E:$E,AF$2,'Mango Blocks - 27.08 - LONG'!$C:$C,$A7)/Z7) -> 0 | AG7: =IF(Z7=0,"NA",COUNTIFS('Mango Blocks - 27.08 - LONG'!$E:$E,AG$2,'Mango Blocks - 27.08 - LONG'!$C:$C,$A7)/Z7) -> 0 | AH7: =IF(AA7="NA","NA",SUM(AB7:AF7)) -> 1
A8: Block1_Q6 | B8: =COUNTIFS('Mango Blocks - 09.05 - LONG'!$E:$E,"<>NA",'Mango Blocks - 09.05 - LONG'!$E:$E,"<>OG",'Mango Blocks - 09.05 - LONG'!$E:$E,"<>-",'Mango Blocks - 09.05 - LONG'!$C:$C,$A8) -> 0 | C8: =IF($B8=0,"NA",COUNTIFS('Mango Blocks - 09.05 - LONG'!$E:$E,"H",'Mango Blocks - 09.05 - LONG'!$C:$C,$A8)) -> NA | D8: =IF($B8=0,"NA",COUNTIFS('Mango Blocks - 09.05 - LONG'!$E:$E,"H",'Mango Blocks - 09.05 - LONG'!$C:$C,$A8)/B8) -> NA | E8: =IF($B8=0,"NA",COUNTIFS('Mango Blocks - 09.05 - LONG'!$E:$E,"PBL",'Mango Blocks - 09.05 - LONG'!$C:$C,$A8)/B8) -> NA | F8: =IF($B8=0,"NA",COUNTIFS('Mango Blocks - 09.05 - LONG'!$E:$E,"FBL",'Mango Blocks - 09.05 - LONG'!$C:$C,$A8)/B8) -> NA | G8: =IF($B8=0,"NA",COUNTIFS('Mango Blocks - 09.05 - LONG'!$E:$E,"PRK",'Mango Blocks - 09.05 - LONG'!$C:$C,$A8)/B8) -> NA | H8: =IF($B8=0,"NA",COUNTIFS('Mango Blocks - 09.05 - LONG'!$E:$E,"FRK",'Mango Blocks - 09.05 - LONG'!$C:$C,$A8)/B8) -> NA | I8: =IF(C8="NA","NA",SUM(D8:H8)) -> NA | J8: =COUNTIFS('Mango Blocks - 13.06 - LONG'!$E:$E,"<>NA",'Mango Blocks - 13.06 - LONG'!$E:$E,"<>OG",'Mango Blocks - 13.06 - LONG'!$E:$E,"<>-",'Mango Blocks - 13.06 - LONG'!$C:$C,$A8) -> 31 | K8: =IF(J8=0,"NA",COUNTIFS('Mango Blocks - 13.06 - LONG'!$E:$E,"H",'Mango Blocks - 13.06 - LONG'!$C:$C,$A8)) -> 15 | L8: =IF(J8=0,"NA",COUNTIFS('Mango Blocks - 13.06 - LONG'!$E:$E,"H",'Mango Blocks - 13.06 - LONG'!$C:$C,$A8)/J8) -> 0.48387097 | M8: =IF(J8=0,"NA",COUNTIFS('Mango Blocks - 13.06 - LONG'!$E:$E,"PBL",'Mango Blocks - 13.06 - LONG'!$C:$C,$A8)/J8) -> 0.4516129 | N8: =IF(J8=0,"NA",COUNTIFS('Mango Blocks - 13.06 - LONG'!$E:$E,"FBL",'Mango Blocks - 13.06 - LONG'!$C:$C,$A8)/J8) -> 0.064516129 | O8: =IF(J8=0,"NA",COUNTIFS('Mango Blocks - 13.06 - LONG'!$E:$E,"PRK",'Mango Blocks - 13.06 - LONG'!$C:$C,$A8)/J8) -> 0 | P8: =IF(J8=0,"NA",COUNTIFS('Mango Blocks - 13.06 - LONG'!$E:$E,"FRK",'Mango Blocks - 13.06 - LONG'!$C:$C,$A8)/J8) -> 0 | Q8: =IF(K8="NA","NA",SUM(L8:P8)) -> 1 | R8: =COUNTIFS('Mango Blocks - 03.08 - LONG'!$E:$E,"<>NA",'Mango Blocks - 03.08 - LONG'!$E:$E,"<>OG",'Mango Blocks - 03.08 - LONG'!$E:$E,"<>-",'Mango Blocks - 03.08 - LONG'!$C:$C,$A8) -> 8 | S8: =IF(R8=0,"NA",COUNTIFS('Mango Blocks - 03.08 - LONG'!$E:$E,"H",'Mango Blocks - 03.08 - LONG'!$C:$C,$A8)) -> 8 | T8: =IF(R8=0,"NA",COUNTIFS('Mango Blocks - 03.08 - LONG'!$E:$E,T$2,'Mango Blocks - 03.08 - LONG'!$C:$C,$A8)/R8) -> 1 | U8: =IF(R8=0,"NA",COUNTIFS('Mango Blocks - 03.08 - LONG'!$E:$E,U$2,'Mango Blocks - 03.08 - LONG'!$C:$C,$A8)/R8) -> 0 | V8: =IF(R8=0,"NA",COUNTIFS('Mango Blocks - 03.08 - LONG'!$E:$E,V$2,'Mango Blocks - 03.08 - LONG'!$C:$C,$A8)/R8) -> 0 | W8: =IF(R8=0,"NA",COUNTIFS('Mango Blocks - 03.08 - LONG'!$E:$E,W$2,'Mango Blocks - 03.08 - LONG'!$C:$C,$A8)/R8) -> 0 | X8: =IF(R8=0,"NA",COUNTIFS('Mango Blocks - 03.08 - LONG'!$E:$E,X$2,'Mango Blocks - 03.08 - LONG'!$C:$C,$A8)/R8) -> 0 | Y8: =IF(S8="NA","NA",SUM(T8:X8)) -> 1 | Z8: =COUNTIFS('Mango Blocks - 27.08 - LONG'!$E:$E,"<>NA",'Mango Blocks - 27.08 - LONG'!$E:$E,"<>OG",'Mango Blocks - 27.08 - LONG'!$E:$E,"<>-",'Mango Blocks - 27.08 - LONG'!$C:$C,$A8) -> 0 | AA8: =IF(Z8=0,"NA",COUNTIFS('Mango Blocks - 27.08 - LONG'!$E:$E,"H",'Mango Blocks - 27.08 - LONG'!$C:$C,$A8)) -> NA | AB8: =IF(Z8=0,"NA",COUNTIFS('Mango Blocks - 27.08 - LONG'!$E:$E,AB$2,'Mango Blocks - 27.08 - LONG'!$C:$C,$A8)/Z8) -> NA | AC8: =IF(Z8=0,"NA",COUNTIFS('Mango Blocks - 27.08 - LONG'!$E:$E,AC$2,'Mango Blocks - 27.08 - LONG'!$C:$C,$A8)/Z8) -> NA | AD8: =IF(Z8=0,"NA",COUNTIFS('Mango Blocks - 27.08 - LONG'!$E:$E,AD$2,'Mango Blocks - 27.08 - LONG'!$C:$C,$A8)/Z8) -> NA | AE8: =IF(Z8=0,"NA",COUNTIFS('Mango Blocks - 27.08 - LONG'!$E:$E,AE$2,'Mango Blocks - 27.08 - LONG'!$C:$C,$A8)/Z8) -> NA | AF8: =IF(Z8=0,"NA",COUNTIFS('Mango Blocks - 27.08 - LONG'!$E:$E,AF$2,'Mango Blocks - 27.08 - LONG'!$C:$C,$A8)/Z8) -> NA | AG8: =IF(Z8=0,"NA",COUNTIFS('Mango Blocks - 27.08 - LONG'!$E:$E,AG$2,'Mango Blocks - 27.08 - LONG'!$C:$C,$A8)/Z8) -> NA | AH8: =IF(AA8="NA","NA",SUM(AB8:AF8)) -> NA
A9: Block1_Q7 | B9: =COUNTIFS('Mango Blocks - 09.05 - LONG'!$E:$E,"<>NA",'Mango Blocks - 09.05 - LONG'!$E:$E,"<>OG",'Mango Blocks - 09.05 - LONG'!$E:$E,"<>-",'Mango Blocks - 09.05 - LONG'!$C:$C,$A9) -> 0 | C9: =IF($B9=0,"NA",COUNTIFS('Mango Blocks - 09.05 - LONG'!$E:$E,"H",'Mango Blocks - 09.05 - LONG'!$C:$C,$A9)) -> NA | D9: =IF($B9=0,"NA",COUNTIFS('Mango Blocks - 09.05 - LONG'!$E:$E,"H",'Mango Blocks - 09.05 - LONG'!$C:$C,$A9)/B9) -> NA | E9: =IF($B9=0,"NA",COUNTIFS('Mango Blocks - 09.05 - LONG'!$E:$E,"PBL",'Mango Blocks - 09.05 - LONG'!$C:$C,$A9)/B9) -> NA | F9: =IF($B9=0,"NA",COUNTIFS('Mango Blocks - 09.05 - LONG'!$E:$E,"FBL",'Mango Blocks - 09.05 - LONG'!$C:$C,$A9)/B9) -> NA | G9: =IF($B9=0,"NA",COUNTIFS('Mango Blocks - 09.05 - LONG'!$E:$E,"PRK",'Mango Blocks - 09.05 - LONG'!$C:$C,$A9)/B9) -> NA | H9: =IF($B9=0,"NA",COUNTIFS('Mango Blocks - 09.05 - LONG'!$E:$E,"FRK",'Mango Blocks - 09.05 - LONG'!$C:$C,$A9)/B9) -> NA | I9: =IF(C9="NA","NA",SUM(D9:H9)) -> NA | J9: =COUNTIFS('Mango Blocks - 13.06 - LONG'!$E:$E,"<>NA",'Mango Blocks - 13.06 - LONG'!$E:$E,"<>OG",'Mango Blocks - 13.06 - LONG'!$E:$E,"<>-",'Mango Blocks - 13.06 - LONG'!$C:$C,$A9) -> 0 | K9: =IF(J9=0,"NA",COUNTIFS('Mango Blocks - 13.06 - LONG'!$E:$E,"H",'Mango Blocks - 13.06 - LONG'!$C:$C,$A9)) -> NA | L9: =IF(J9=0,"NA",COUNTIFS('Mango Blocks - 13.06 - LONG'!$E:$E,"H",'Mango Blocks - 13.06 - LONG'!$C:$C,$A9)/J9) -> NA | M9: =IF(J9=0,"NA",COUNTIFS('Mango Blocks - 13.06 - LONG'!$E:$E,"PBL",'Mango Blocks - 13.06 - LONG'!$C:$C,$A9)/J9) -> NA | N9: =IF(J9=0,"NA",COUNTIFS('Mango Blocks - 13.06 - LONG'!$E:$E,"FBL",'Mango Blocks - 13.06 - LONG'!$C:$C,$A9)/J9) -> NA | O9: =IF(J9=0,"NA",COUNTIFS('Mango Blocks - 13.06 - LONG'!$E:$E,"PRK",'Mango Blocks - 13.06 - LONG'!$C:$C,$A9)/J9) -> NA | P9: =IF(J9=0,"NA",COUNTIFS('Mango Blocks - 13.06 - LONG'!$E:$E,"FRK",'Mango Blocks - 13.06 - LONG'!$C:$C,$A9)/J9) -> NA | Q9: =IF(K9="NA","NA",SUM(L9:P9)) -> NA | R9: =COUNTIFS('Mango Blocks - 03.08 - LONG'!$E:$E,"<>NA",'Mango Blocks - 03.08 - LONG'!$E:$E,"<>OG",'Mango Blocks - 03.08 - LONG'!$E:$E,"<>-",'Mango Blocks - 03.08 - LONG'!$C:$C,$A9) -> 0 | S9: =IF(R9=0,"NA",COUNTIFS('Mango Blocks - 03.08 - LONG'!$E:$E,"H",'Mango Blocks - 03.08 - LONG'!$C:$C,$A9)) -> NA | T9: =IF(R9=0,"NA",COUNTIFS('Mango Blocks - 03.08 - LONG'!$E:$E,T$2,'Mango Blocks - 03.08 - LONG'!$C:$C,$A9)/R9) -> NA | U9: =IF(R9=0,"NA",COUNTIFS('Mango Blocks - 03.08 - LONG'!$E:$E,U$2,'Mango Blocks - 03.08 - LONG'!$C:$C,$A9)/R9) -> NA | V9: =IF(R9=0,"NA",COUNTIFS('Mango Blocks - 03.08 - LONG'!$E:$E,V$2,'Mango Blocks - 03.08 - LONG'!$C:$C,$A9)/R9) -> NA | W9: =IF(R9=0,"NA",COUNTIFS('Mango Blocks - 03.08 - LONG'!$E:$E,W$2,'Mango Blocks - 03.08 - LONG'!$C:$C,$A9)/R9) -> NA | X9: =IF(R9=0,"NA",COUNTIFS('Mango Blocks - 03.08 - LONG'!$E:$E,X$2,'Mango Blocks - 03.08 - LONG'!$C:$C,$A9)/R9) -> NA | Y9: =IF(S9="NA","NA",SUM(T9:X9)) -> NA | Z9: =COUNTIFS('Mango Blocks - 27.08 - LONG'!$E:$E,"<>NA",'Mango Blocks - 27.08 - LONG'!$E:$E,"<>OG",'Mango Blocks - 27.08 - LONG'!$E:$E,"<>-",'Mango Blocks - 27.08 - LONG'!$C:$C,$A9) -> 0 | AA9: =IF(Z9=0,"NA",COUNTIFS('Mango Blocks - 27.08 - LONG'!$E:$E,"H",'Mango Blocks - 27.08 - LONG'!$C:$C,$A9)) -> NA | AB9: =IF(Z9=0,"NA",COUNTIFS('Mango Blocks - 27.08 - LONG'!$E:$E,AB$2,'Mango Blocks - 27.08 - LONG'!$C:$C,$A9)/Z9) -> NA | AC9: =IF(Z9=0,"NA",COUNTIFS('Mango Blocks - 27.08 - LONG'!$E:$E,AC$2,'Mango Blocks - 27.08 - LONG'!$C:$C,$A9)/Z9) -> NA | AD9: =IF(Z9=0,"NA",COUNTIFS('Mango Blocks - 27.08 - LONG'!$E:$E,AD$2,'Mango Blocks - 27.08 - LONG'!$C:$C,$A9)/Z9) -> NA | AE9: =IF(Z9=0,"NA",COUNTIFS('Mango Blocks - 27.08 - LONG'!$E:$E,AE$2,'Mango Blocks - 27.08 - LONG'!$C:$C,$A9)/Z9) -> NA | AF9: =IF(Z9=0,"NA",COUNTIFS('Mango Blocks - 27.08 - LONG'!$E:$E,AF$2,'Mango Blocks - 27.08 - LONG'!$C:$C,$A9)/Z9) -> NA | AG9: =IF(Z9=0,"NA",COUNTIFS('Mango Blocks - 27.08 - LONG'!$E:$E,AG$2,'Mango Blocks - 27.08 - LONG'!$C:$C,$A9)/Z9) -> NA | AH9: =IF(AA9="NA","NA",SUM(AB9:AF9)) -> NA
A10: Block1_Q8 | B10: =COUNTIFS('Mango Blocks - 09.05 - LONG'!$E:$E,"<>NA",'Mango Blocks - 09.05 - LONG'!$E:$E,"<>OG",'Mango Blocks - 09.05 - LONG'!$E:$E,"<>-",'Mango Blocks - 09.05 - LONG'!$C:$C,$A10) -> 3 | C10: =IF($B10=0,"NA",COUNTIFS('Mango Blocks - 09.05 - LONG'!$E:$E,"H",'Mango Blocks - 09.05 - LONG'!$C:$C,$A10)) -> 0 | D10: =IF($B10=0,"NA",COUNTIFS('Mango Blocks - 09.05 - LONG'!$E:$E,"H",'Mango Blocks - 09.05 - LONG'!$C:$C,$A10)/B10) -> 0 | E10: =IF($B10=0,"NA",COUNTIFS('Mango Blocks - 09.05 - LONG'!$E:$E,"PBL",'Mango Blocks - 09.05 - LONG'!$C:$C,$A10)/B10) -> 1 | F10: =IF($B10=0,"NA",COUNTIFS('Mango Blocks - 09.05 - LONG'!$E:$E,"FBL",'Mango Blocks - 09.05 - LONG'!$C:$C,$A10)/B10) -> 0 | G10: =IF($B10=0,"NA",COUNTIFS('Mango Blocks - 09.05 - LONG'!$E:$E,"PRK",'Mango Blocks - 09.05 - LONG'!$C:$C,$A10)/B10) -> 0 | H10: =IF($B10=0,"NA",COUNTIFS('Mango Blocks - 09.05 - LONG'!$E:$E,"FRK",'Mango Blocks - 09.05 - LONG'!$C:$C,$A10)/B10) -> 0 | I10: =IF(C10="NA","NA",SUM(D10:H10)) -> 1 | J10: =COUNTIFS('Mango Blocks - 13.06 - LONG'!$E:$E,"<>NA",'Mango Blocks - 13.06 - LONG'!$E:$E,"<>OG",'Mango Blocks - 13.06 - LONG'!$E:$E,"<>-",'Mango Blocks - 13.06 - LONG'!$C:$C,$A10) -> 13 | K10: =IF(J10=0,"NA",COUNTIFS('Mango Blocks - 13.06 - LONG'!$E:$E,"H",'Mango Blocks - 13.06 - LONG'!$C:$C,$A10)) -> 9 | L10: =IF(J10=0,"NA",COUNTIFS('Mango Blocks - 13.06 - LONG'!$E:$E,"H",'Mango Blocks - 13.06 - LONG'!$C:$C,$A10)/J10) -> 0.69230769 | M10: =IF(J10=0,"NA",COUNTIFS('Mango Blocks - 13.06 - LONG'!$E:$E,"PBL",'Mango Blocks - 13.06 - LONG'!$C:$C,$A10)/J10) -> 0 | N10: =IF(J10=0,"NA",COUNTIFS('Mango Blocks - 13.06 - LONG'!$E:$E,"FBL",'Mango Blocks - 13.06 - LONG'!$C:$C,$A10)/J10) -> 0 | O10: =IF(J10=0,"NA",COUNTIFS('Mango Blocks - 13.06 - LONG'!$E:$E,"PRK",'Mango Blocks - 13.06 - LONG'!$C:$C,$A10)/J10) -> 0.30769231 | P10: =IF(J10=0,"NA",COUNTIFS('Mango Blocks - 13.06 - LONG'!$E:$E,"FRK",'Mango Blocks - 13.06 - LONG'!$C:$C,$A10)/J10) -> 0 | Q10: =IF(K10="NA","NA",SUM(L10:P10)) -> 1 | R10: =COUNTIFS('Mango Blocks - 03.08 - LONG'!$E:$E,"<>NA",'Mango Blocks - 03.08 - LONG'!$E:$E,"<>OG",'Mango Blocks - 03.08 - LONG'!$E:$E,"<>-",'Mango Blocks - 03.08 - LONG'!$C:$C,$A10) -> 0 | S10: =IF(R10=0,"NA",COUNTIFS('Mango Blocks - 03.08 - LONG'!$E:$E,"H",'Mango Blocks - 03.08 - LONG'!$C:$C,$A10)) -> NA | T10: =IF(R10=0,"NA",COUNTIFS('Mango Blocks - 03.08 - LONG'!$E:$E,T$2,'Mango Blocks - 03.08 - LONG'!$C:$C,$A10)/R10) -> NA | U10: =IF(R10=0,"NA",COUNTIFS('Mango Blocks - 03.08 - LONG'!$E:$E,U$2,'Mango Blocks - 03.08 - LONG'!$C:$C,$A10)/R10) -> NA | V10: =IF(R10=0,"NA",COUNTIFS('Mango Blocks - 03.08 - LONG'!$E:$E,V$2,'Mango Blocks - 03.08 - LONG'!$C:$C,$A10)/R10) -> NA | W10: =IF(R10=0,"NA",COUNTIFS('Mango Blocks - 03.08 - LONG'!$E:$E,W$2,'Mango Blocks - 03.08 - LONG'!$C:$C,$A10)/R10) -> NA | X10: =IF(R10=0,"NA",COUNTIFS('Mango Blocks - 03.08 - LONG'!$E:$E,X$2,'Mango Blocks - 03.08 - LONG'!$C:$C,$A10)/R10) -> NA | Y10: =IF(S10="NA","NA",SUM(T10:X10)) -> NA | Z10: =COUNTIFS('Mango Blocks - 27.08 - LONG'!$E:$E,"<>NA",'Mango Blocks - 27.08 - LONG'!$E:$E,"<>OG",'Mango Blocks - 27.08 - LONG'!$E:$E,"<>-",'Mango Blocks - 27.08 - LONG'!$C:$C,$A10) -> 0 | AA10: =IF(Z10=0,"NA",COUNTIFS('Mango Blocks - 27.08 - LONG'!$E:$E,"H",'Mango Blocks - 27.08 - LONG'!$C:$C,$A10)) -> NA | AB10: =IF(Z10=0,"NA",COUNTIFS('Mango Blocks - 27.08 - LONG'!$E:$E,AB$2,'Mango Blocks - 27.08 - LONG'!$C:$C,$A10)/Z10) -> NA | AC10: =IF(Z10=0,"NA",COUNTIFS('Mango Blocks - 27.08 - LONG'!$E:$E,AC$2,'Mango Blocks - 27.08 - LONG'!$C:$C,$A10)/Z10) -> NA | AD10: =IF(Z10=0,"NA",COUNTIFS('Mango Blocks - 27.08 - LONG'!$E:$E,AD$2,'Mango Blocks - 27.08 - LONG'!$C:$C,$A10)/Z10) -> NA | AE10: =IF(Z10=0,"NA",COUNTIFS('Mango Blocks - 27.08 - LONG'!$E:$E,AE$2,'Mango Blocks - 27.08 - LONG'!$C:$C,$A10)/Z10) -> NA | AF10: =IF(Z10=0,"NA",COUNTIFS('Mango Blocks - 27.08 - LONG'!$E:$E,AF$2,'Mango Blocks - 27.08 - LONG'!$C:$C,$A10)/Z10) -> NA | AG10: =IF(Z10=0,"NA",COUNTIFS('Mango Blocks - 27.08 - LONG'!$E:$E,AG$2,'Mango Blocks - 27.08 - LONG'!$C:$C,$A10)/Z10) -> NA | AH10: =IF(AA10="NA","NA",SUM(AB10:AF10)) -> NA
A11: Block1_Q9 | B11: =COUNTIFS('Mango Blocks - 09.05 - LONG'!$E:$E,"<>NA",'Mango Blocks - 09.05 - LONG'!$E:$E,"<>OG",'Mango Blocks - 09.05 - LONG'!$E:$E,"<>-",'Mango Blocks - 09.05 - LONG'!$C:$C,$A11) -> 13 | C11: =IF($B11=0,"NA",COUNTIFS('Mango Blocks - 09.05 - LONG'!$E:$E,"H",'Mango Blocks - 09.05 - LONG'!$C:$C,$A11)) -> 0 | D11: =IF($B11=0,"NA",COUNTIFS('Mango Blocks - 09.05 - LONG'!$E:$E,"H",'Mango Blocks - 09.05 - LONG'!$C:$C,$A11)/B11) -> 0 | E11: =IF($B11=0,"NA",COUNTIFS('Mango Blocks - 09.05 - LONG'!$E:$E,"PBL",'Mango Blocks - 09.05 - LONG'!$C:$C,$A11)/B11) -> 0.23076923 | F11: =IF($B11=0,"NA",COUNTIFS('Mango Blocks - 09.05 - LONG'!$E:$E,"FBL",'Mango Blocks - 09.05 - LONG'!$C:$C,$A11)/B11) -> 0 | G11: =IF($B11=0,"NA",COUNTIFS('Mango Blocks - 09.05 - LONG'!$E:$E,"PRK",'Mango Blocks - 09.05 - LONG'!$C:$C,$A11)/B11) -> 0 | H11: =IF($B11=0,"NA",COUNTIFS('Mango Blocks - 09.05 - LONG'!$E:$E,"FRK",'Mango Blocks - 09.05 - LONG'!$C:$C,$A11)/B11) -> 0.76923077 | I11: =IF(C11="NA","NA",SUM(D11:H11)) -> 1 | J11: =COUNTIFS('Mango Blocks - 13.06 - LONG'!$E:$E,"<>NA",'Mango Blocks - 13.06 - LONG'!$E:$E,"<>OG",'Mango Blocks - 13.06 - LONG'!$E:$E,"<>-",'Mango Blocks - 13.06 - LONG'!$C:$C,$A11) -> 6 | K11: =IF(J11=0,"NA",COUNTIFS('Mango Blocks - 13.06 - LONG'!$E:$E,"H",'Mango Blocks - 13.06 - LONG'!$C:$C,$A11)) -> 0 | L11: =IF(J11=0,"NA",COUNTIFS('Mango Blocks - 13.06 - LONG'!$E:$E,"H",'Mango Blocks - 13.06 - LONG'!$C:$C,$A11)/J11) -> 0 | M11: =IF(J11=0,"NA",COUNTIFS('Mango Blocks - 13.06 - LONG'!$E:$E,"PBL",'Mango Blocks - 13.06 - LONG'!$C:$C,$A11)/J11) -> 0 | N11: =IF(J11=0,"NA",COUNTIFS('Mango Blocks - 13.06 - LONG'!$E:$E,"FBL",'Mango Blocks - 13.06 - LONG'!$C:$C,$A11)/J11) -> 1 | O11: =IF(J11=0,"NA",COUNTIFS('Mango Blocks - 13.06 - LONG'!$E:$E,"PRK",'Mango Blocks - 13.06 - LONG'!$C:$C,$A11)/J11) -> 0 | P11: =IF(J11=0,"NA",COUNTIFS('Mango Blocks - 13.06 - LONG'!$E:$E,"FRK",'Mango Blocks - 13.06 - LONG'!$C:$C,$A11)/J11) -> 0 | Q11: =IF(K11="NA","NA",SUM(L11:P11)) -> 1 | R11: =COUNTIFS('Mango Blocks - 03.08 - LONG'!$E:$E,"<>NA",'Mango Blocks - 03.08 - LONG'!$E:$E,"<>OG",'Mango Blocks - 03.08 - LONG'!$E:$E,"<>-",'Mango Blocks - 03.08 - LONG'!$C:$C,$A11) -> 14 | S11: =IF(R11=0,"NA",COUNTIFS('Mango Blocks - 03.08 - LONG'!$E:$E,"H",'Mango Blocks - 03.08 - LONG'!$C:$C,$A11)) -> 0 | T11: =IF(R11=0,"NA",COUNTIFS('Mango Blocks - 03.08 - LONG'!$E:$E,T$2,'Mango Blocks - 03.08 - LONG'!$C:$C,$A11)/R11) -> 0 | U11: =IF(R11=0,"NA",COUNTIFS('Mango Blocks - 03.08 - LONG'!$E:$E,U$2,'Mango Blocks - 03.08 - LONG'!$C:$C,$A11)/R11) -> 0.071428571 | V11: =IF(R11=0,"NA",COUNTIFS('Mango Blocks - 03.08 - LONG'!$E:$E,V$2,'Mango Blocks - 03.08 - LONG'!$C:$C,$A11)/R11) -> 0 | W11: =IF(R11=0,"NA",COUNTIFS('Mango Blocks - 03.08 - LONG'!$E:$E,W$2,'Mango Blocks - 03.08 - LONG'!$C:$C,$A11)/R11) -> 0 | X11: =IF(R11=0,"NA",COUNTIFS('Mango Blocks - 03.08 - LONG'!$E:$E,X$2,'Mango Blocks - 03.08 - LONG'!$C:$C,$A11)/R11) -> 0.92857143 | Y11: =IF(S11="NA","NA",SUM(T11:X11)) -> 1 | Z11: =COUNTIFS('Mango Blocks - 27.08 - LONG'!$E:$E,"<>NA",'Mango Blocks - 27.08 - LONG'!$E:$E,"<>OG",'Mango Blocks - 27.08 - LONG'!$E:$E,"<>-",'Mango Blocks - 27.08 - LONG'!$C:$C,$A11) -> 12 | AA11: =IF(Z11=0,"NA",COUNTIFS('Mango Blocks - 27.08 - LONG'!$E:$E,"H",'Mango Blocks - 27.08 - LONG'!$C:$C,$A11)) -> 0 | AB11: =IF(Z11=0,"NA",COUNTIFS('Mango Blocks - 27.08 - LONG'!$E:$E,AB$2,'Mango Blocks - 27.08 - LONG'!$C:$C,$A11)/Z11) -> 0 | AC11: =IF(Z11=0,"NA",COUNTIFS('Mango Blocks - 27.08 - LONG'!$E:$E,AC$2,'Mango Blocks - 27.08 - LONG'!$C:$C,$A11)/Z11) -> 0 | AD11: =IF(Z11=0,"NA",COUNTIFS('Mango Blocks - 27.08 - LONG'!$E:$E,AD$2,'Mango Blocks - 27.08 - LONG'!$C:$C,$A11)/Z11) -> 0.25 | AE11: =IF(Z11=0,"NA",COUNTIFS('Mango Blocks - 27.08 - LONG'!$E:$E,AE$2,'Mango Blocks - 27.08 - LONG'!$C:$C,$A11)/Z11) -> 0 | AF11: =IF(Z11=0,"NA",COUNTIFS('Mango Blocks - 27.08 - LONG'!$E:$E,AF$2,'Mango Blocks - 27.08 - LONG'!$C:$C,$A11)/Z11) -> 0.75 | AG11: =IF(Z11=0,"NA",COUNTIFS('Mango Blocks - 27.08 - LONG'!$E:$E,AG$2,'Mango Blocks - 27.08 - LONG'!$C:$C,$A11)/Z11) -> 0 | AH11: =IF(AA11="NA","NA",SUM(AB11:AF11)) -> 1
A12: Block1_Q10 | B12: =COUNTIFS('Mango Blocks - 09.05 - LONG'!$E:$E,"<>NA",'Mango Blocks - 09.05 - LONG'!$E:$E,"<>OG",'Mango Blocks - 09.05 - LONG'!$E:$E,"<>-",'Mango Blocks - 09.05 - LONG'!$C:$C,$A12) -> 0 | C12: =IF($B12=0,"NA",COUNTIFS('Mango Blocks - 09.05 - LONG'!$E:$E,"H",'Mango Blocks - 09.05 - LONG'!$C:$C,$A12)) -> NA | D12: =IF($B12=0,"NA",COUNTIFS('Mango Blocks - 09.05 - LONG'!$E:$E,"H",'Mango Blocks - 09.05 - LONG'!$C:$C,$A12)/B12) -> NA | E12: =IF($B12=0,"NA",COUNTIFS('Mango Blocks - 09.05 - LONG'!$E:$E,"PBL",'Mango Blocks - 09.05 - LONG'!$C:$C,$A12)/B12) -> NA | F12: =IF($B12=0,"NA",COUNTIFS('Mango Blocks - 09.05 - LONG'!$E:$E,"FBL",'Mango Blocks - 09.05 - LONG'!$C:$C,$A12)/B12) -> NA | G12: =IF($B12=0,"NA",COUNTIFS('Mango Blocks - 09.05 - LONG'!$E:$E,"PRK",'Mango Blocks - 09.05 - LONG'!$C:$C,$A12)/B12) -> NA | H12: =IF($B12=0,"NA",COUNTIFS('Mango Blocks - 09.05 - LONG'!$E:$E,"FRK",'Mango Blocks - 09.05 - LONG'!$C:$C,$A12)/B12) -> NA | I12: =IF(C12="NA","NA",SUM(D12:H12)) -> NA | J12: =COUNTIFS('Mango Blocks - 13.06 - LONG'!$E:$E,"<>NA",'Mango Blocks - 13.06 - LONG'!$E:$E,"<>OG",'Mango Blocks - 13.06 - LONG'!$E:$E,"<>-",'Mango Blocks - 13.06 - LONG'!$C:$C,$A12) -> 0 | K12: =IF(J12=0,"NA",COUNTIFS('Mango Blocks - 13.06 - LONG'!$E:$E,"H",'Mango Blocks - 13.06 - LONG'!$C:$C,$A12)) -> NA | L12: =IF(J12=0,"NA",COUNTIFS('Mango Blocks - 13.06 - LONG'!$E:$E,"H",'Mango Blocks - 13.06 - LONG'!$C:$C,$A12)/J12) -> NA | M12: =IF(J12=0,"NA",COUNTIFS('Mango Blocks - 13.06 - LONG'!$E:$E,"PBL",'Mango Blocks - 13.06 - LONG'!$C:$C,$A12)/J12) -> NA | N12: =IF(J12=0,"NA",COUNTIFS('Mango Blocks - 13.06 - LONG'!$E:$E,"FBL",'Mango Blocks - 13.06 - LONG'!$C:$C,$A12)/J12) -> NA | O12: =IF(J12=0,"NA",COUNTIFS('Mango Blocks - 13.06 - LONG'!$E:$E,"PRK",'Mango Blocks - 13.06 - LONG'!$C:$C,$A12)/J12) -> NA | P12: =IF(J12=0,"NA",COUNTIFS('Mango Blocks - 13.06 - LONG'!$E:$E,"FRK",'Mango Blocks - 13.06 - LONG'!$C:$C,$A12)/J12) -> NA | Q12: =IF(K12="NA","NA",SUM(L12:P12)) -> NA | R12: =COUNTIFS('Mango Blocks - 03.08 - LONG'!$E:$E,"<>NA",'Mango Blocks - 03.08 - LONG'!$E:$E,"<>OG",'Mango Blocks - 03.08 - LONG'!$E:$E,"<>-",'Mango Blocks - 03.08 - LONG'!$C:$C,$A12) -> 27 | S12: =IF(R12=0,"NA",COUNTIFS('Mango Blocks - 03.08 - LONG'!$E:$E,"H",'Mango Blocks - 03.08 - LONG'!$C:$C,$A12)) -> 0 | T12: =IF(R12=0,"NA",COUNTIFS('Mango Blocks - 03.08 - LONG'!$E:$E,T$2,'Mango Blocks - 03.08 - LONG'!$C:$C,$A12)/R12) -> 0 | U12: =IF(R12=0,"NA",COUNTIFS('Mango Blocks - 03.08 - LONG'!$E:$E,U$2,'Mango Blocks - 03.08 - LONG'!$C:$C,$A12)/R12) -> 0.11111111 | V12: =IF(R12=0,"NA",COUNTIFS('Mango Blocks - 03.08 - LONG'!$E:$E,V$2,'Mango Blocks - 03.08 - LONG'!$C:$C,$A12)/R12) -> 0 | W12: =IF(R12=0,"NA",COUNTIFS('Mango Blocks - 03.08 - LONG'!$E:$E,W$2,'Mango Blocks - 03.08 - LONG'!$C:$C,$A12)/R12) -> 0 | X12: =IF(R12=0,"NA",COUNTIFS('Mango Blocks - 03.08 - LONG'!$E:$E,X$2,'Mango Blocks - 03.08 - LONG'!$C:$C,$A12)/R12) -> 0.88888889 | Y12: =IF(S12="NA","NA",SUM(T12:X12)) -> 1 | Z12: =COUNTIFS('Mango Blocks - 27.08 - LONG'!$E:$E,"<>NA",'Mango Blocks - 27.08 - LONG'!$E:$E,"<>OG",'Mango Blocks - 27.08 - LONG'!$E:$E,"<>-",'Mango Blocks - 27.08 - LONG'!$C:$C,$A12) -> 12 | AA12: =IF(Z12=0,"NA",COUNTIFS('Mango Blocks - 27.08 - LONG'!$E:$E,"H",'Mango Blocks - 27.08 - LONG'!$C:$C,$A12)) -> 0 | AB12: =IF(Z12=0,"NA",COUNTIFS('Mango Blocks - 27.08 - LONG'!$E:$E,AB$2,'Mango Blocks - 27.08 - LONG'!$C:$C,$A12)/Z12) -> 0 | AC12: =IF(Z12=0,"NA",COUNTIFS('Mango Blocks - 27.08 - LONG'!$E:$E,AC$2,'Mango Blocks - 27.08 - LONG'!$C:$C,$A12)/Z12) -> 0.083333333 | AD12: =IF(Z12=0,"NA",COUNTIFS('Mango Blocks - 27.08 - LONG'!$E:$E,AD$2,'Mango Blocks - 27.08 - LONG'!$C:$C,$A12)/Z12) -> 0 | AE12: =IF(Z12=0,"NA",COUNTIFS('Mango Blocks - 27.08 - LONG'!$E:$E,AE$2,'Mango Blocks - 27.08 - LONG'!$C:$C,$A12)/Z12) -> 0 | AF12: =IF(Z12=0,"NA",COUNTIFS('Mango Blocks - 27.08 - LONG'!$E:$E,AF$2,'Mango Blocks - 27.08 - LONG'!$C:$C,$A12)/Z12) -> 0.91666667 | AG12: =IF(Z12=0,"NA",COUNTIFS('Mango Blocks - 27.08 - LONG'!$E:$E,AG$2,'Mango Blocks - 27.08 - LONG'!$C:$C,$A12)/Z12) -> 0 | AH12: =IF(AA12="NA","NA",SUM(AB12:AF12)) -> 1
A13: Block2_Q1 | B13: =COUNTIFS('Mango Blocks - 09.05 - LONG'!$E:$E,"<>NA",'Mango Blocks - 09.05 - LONG'!$E:$E,"<>OG",'Mango Blocks - 09.05 - LONG'!$E:$E,"<>-",'Mango Blocks - 09.05 - LONG'!$C:$C,$A13) -> 0 | C13: =IF($B13=0,"NA",COUNTIFS('Mango Blocks - 09.05 - LONG'!$E:$E,"H",'Mango Blocks - 09.05 - LONG'!$C:$C,$A13)) -> NA | D13: =IF($B13=0,"NA",COUNTIFS('Mango Blocks - 09.05 - LONG'!$E:$E,"H",'Mango Blocks - 09.05 - LONG'!$C:$C,$A13)/B13) -> NA | E13: =IF($B13=0,"NA",COUNTIFS('Mango Blocks - 09.05 - LONG'!$E:$E,"PBL",'Mango Blocks - 09.05 - LONG'!$C:$C,$A13)/B13) -> NA | F13: =IF($B13=0,"NA",COUNTIFS('Mango Blocks - 09.05 - LONG'!$E:$E,"FBL",'Mango Blocks - 09.05 - LONG'!$C:$C,$A13)/B13) -> NA | G13: =IF($B13=0,"NA",COUNTIFS('Mango Blocks - 09.05 - LONG'!$E:$E,"PRK",'Mango Blocks - 09.05 - LONG'!$C:$C,$A13)/B13) -> NA | H13: =IF($B13=0,"NA",COUNTIFS('Mango Blocks - 09.05 - LONG'!$E:$E,"FRK",'Mango Blocks - 09.05 - LONG'!$C:$C,$A13)/B13) -> NA | I13: =IF(C13="NA","NA",SUM(D13:H13)) -> NA | J13: =COUNTIFS('Mango Blocks - 13.06 - LONG'!$E:$E,"<>NA",'Mango Blocks - 13.06 - LONG'!$E:$E,"<>OG",'Mango Blocks - 13.06 - LONG'!$E:$E,"<>-",'Mango Blocks - 13.06 - LONG'!$C:$C,$A13) -> 0 | K13: =IF(J13=0,"NA",COUNTIFS('Mango Blocks - 13.06 - LONG'!$E:$E,"H",'Mango Blocks - 13.06 - LONG'!$C:$C,$A13)) -> NA | L13: =IF(J13=0,"NA",COUNTIFS('Mango Blocks - 13.06 - LONG'!$E:$E,"H",'Mango Blocks - 13.06 - LONG'!$C:$C,$A13)/J13) -> NA | M13: =IF(J13=0,"NA",COUNTIFS('Mango Blocks - 13.06 - LONG'!$E:$E,"PBL",'Mango Blocks - 13.06 - LONG'!$C:$C,$A13)/J13) -> NA | N13: =IF(J13=0,"NA",COUNTIFS('Mango Blocks - 13.06 - LONG'!$E:$E,"FBL",'Mango Blocks - 13.06 - LONG'!$C:$C,$A13)/J13) -> NA | O13: =IF(J13=0,"NA",COUNTIFS('Mango Blocks - 13.06 - LONG'!$E:$E,"PRK",'Mango Blocks - 13.06 - LONG'!$C:$C,$A13)/J13) -> NA | P13: =IF(J13=0,"NA",COUNTIFS('Mango Blocks - 13.06 - LONG'!$E:$E,"FRK",'Mango Blocks - 13.06 - LONG'!$C:$C,$A13)/J13) -> NA | Q13: =IF(K13="NA","NA",SUM(L13:P13)) -> NA | R13: =COUNTIFS('Mango Blocks - 03.08 - LONG'!$E:$E,"<>NA",'Mango Blocks - 03.08 - LONG'!$E:$E,"<>OG",'Mango Blocks - 03.08 - LONG'!$E:$E,"<>-",'Mango Blocks - 03.08 - LONG'!$C:$C,$A13) -> 0 | S13: =IF(R13=0,"NA",COUNTIFS('Mango Blocks - 03.08 - LONG'!$E:$E,"H",'Mango Blocks - 03.08 - LONG'!$C:$C,$A13)) -> NA | T13: =IF(R13=0,"NA",COUNTIFS('Mango Blocks - 03.08 - LONG'!$E:$E,T$2,'Mango Blocks - 03.08 - LONG'!$C:$C,$A13)/R13) -> NA | U13: =IF(R13=0,"NA",COUNTIFS('Mango Blocks - 03.08 - LONG'!$E:$E,U$2,'Mango Blocks - 03.08 - LONG'!$C:$C,$A13)/R13) -> NA | V13: =IF(R13=0,"NA",COUNTIFS('Mango Blocks - 03.08 - LONG'!$E:$E,V$2,'Mango Blocks - 03.08 - LONG'!$C:$C,$A13)/R13) -> NA | W13: =IF(R13=0,"NA",COUNTIFS('Mango Blocks - 03.08 - LONG'!$E:$E,W$2,'Mango Blocks - 03.08 - LONG'!$C:$C,$A13)/R13) -> NA | X13: =IF(R13=0,"NA",COUNTIFS('Mango Blocks - 03.08 - LONG'!$E:$E,X$2,'Mango Blocks - 03.08 - LONG'!$C:$C,$A13)/R13) -> NA | Y13: =IF(S13="NA","NA",SUM(T13:X13)) -> NA | Z13: =COUNTIFS('Mango Blocks - 27.08 - LONG'!$E:$E,"<>NA",'Mango Blocks - 27.08 - LONG'!$E:$E,"<>OG",'Mango Blocks - 27.08 - LONG'!$E:$E,"<>-",'Mango Blocks - 27.08 - LONG'!$C:$C,$A13) -> 16 | AA13: =IF(Z13=0,"NA",COUNTIFS('Mango Blocks - 27.08 - LONG'!$E:$E,"H",'Mango Blocks - 27.08 - LONG'!$C:$C,$A13)) -> 7 | AB13: =IF(Z13=0,"NA",COUNTIFS('Mango Blocks - 27.08 - LONG'!$E:$E,AB$2,'Mango Blocks - 27.08 - LONG'!$C:$C,$A13)/Z13) -> 0.4375 | AC13: =IF(Z13=0,"NA",COUNTIFS('Mango Blocks - 27.08 - LONG'!$E:$E,AC$2,'Mango Blocks - 27.08 - LONG'!$C:$C,$A13)/Z13) -> 0 | AD13: =IF(Z13=0,"NA",COUNTIFS('Mango Blocks - 27.08 - LONG'!$E:$E,AD$2,'Mango Blocks - 27.08 - LONG'!$C:$C,$A13)/Z13) -> 0 | AE13: =IF(Z13=0,"NA",COUNTIFS('Mango Blocks - 27.08 - LONG'!$E:$E,AE$2,'Mango Blocks - 27.08 - LONG'!$C:$C,$A13)/Z13) -> 0.125 | AF13: =IF(Z13=0,"NA",COUNTIFS('Mango Blocks - 27.08 - LONG'!$E:$E,AF$2,'Mango Blocks - 27.08 - LONG'!$C:$C,$A13)/Z13) -> 0.125 | AG13: =IF(Z13=0,"NA",COUNTIFS('Mango Blocks - 27.08 - LONG'!$E:$E,AG$2,'Mango Blocks - 27.08 - LONG'!$C:$C,$A13)/Z13) -> 0.3125 | AH13: =IF(AA13="NA","NA",SUM(AB13:AG13)) -> 1
A14: Block2_Q2 | B14: =COUNTIFS('Mango Blocks - 09.05 - LONG'!$E:$E,"<>NA",'Mango Blocks - 09.05 - LONG'!$E:$E,"<>OG",'Mango Blocks - 09.05 - LONG'!$E:$E,"<>-",'Mango Blocks - 09.05 - LONG'!$C:$C,$A14) -> 0 | C14: =IF($B14=0,"NA",COUNTIFS('Mango Blocks - 09.05 - LONG'!$E:$E,"H",'Mango Blocks - 09.05 - LONG'!$C:$C,$A14)) -> NA | D14: =IF($B14=0,"NA",COUNTIFS('Mango Blocks - 09.05 - LONG'!$E:$E,"H",'Mango Blocks - 09.05 - LONG'!$C:$C,$A14)/B14) -> NA | E14: =IF($B14=0,"NA",COUNTIFS('Mango Blocks - 09.05 - LONG'!$E:$E,"PBL",'Mango Blocks - 09.05 - LONG'!$C:$C,$A14)/B14) -> NA | F14: =IF($B14=0,"NA",COUNTIFS('Mango Blocks - 09.05 - LONG'!$E:$E,"FBL",'Mango Blocks - 09.05 - LONG'!$C:$C,$A14)/B14) -> NA | G14: =IF($B14=0,"NA",COUNTIFS('Mango Blocks - 09.05 - LONG'!$E:$E,"PRK",'Mango Blocks - 09.05 - LONG'!$C:$C,$A14)/B14) -> NA | H14: =IF($B14=0,"NA",COUNTIFS('Mango Blocks - 09.05 - LONG'!$E:$E,"FRK",'Mango Blocks - 09.05 - LONG'!$C:$C,$A14)/B14) -> NA | I14: =IF(C14="NA","NA",SUM(D14:H14)) -> NA | J14: =COUNTIFS('Mango Blocks - 13.06 - LONG'!$E:$E,"<>NA",'Mango Blocks - 13.06 - LONG'!$E:$E,"<>OG",'Mango Blocks - 13.06 - LONG'!$E:$E,"<>-",'Mango Blocks - 13.06 - LONG'!$C:$C,$A14) -> 0 | K14: =IF(J14=0,"NA",COUNTIFS('Mango Blocks - 13.06 - LONG'!$E:$E,"H",'Mango Blocks - 13.06 - LONG'!$C:$C,$A14)) -> NA | L14: =IF(J14=0,"NA",COUNTIFS('Mango Blocks - 13.06 - LONG'!$E:$E,"H",'Mango Blocks - 13.06 - LONG'!$C:$C,$A14)/J14) -> NA | M14: =IF(J14=0,"NA",COUNTIFS('Mango Blocks - 13.06 - LONG'!$E:$E,"PBL",'Mango Blocks - 13.06 - LONG'!$C:$C,$A14)/J14) -> NA | N14: =IF(J14=0,"NA",COUNTIFS('Mango Blocks - 13.06 - LONG'!$E:$E,"FBL",'Mango Blocks - 13.06 - LONG'!$C:$C,$A14)/J14) -> NA | O14: =IF(J14=0,"NA",COUNTIFS('Mango Blocks - 13.06 - LONG'!$E:$E,"PRK",'Mango Blocks - 13.06 - LONG'!$C:$C,$A14)/J14) -> NA | P14: =IF(J14=0,"NA",COUNTIFS('Mango Blocks - 13.06 - LONG'!$E:$E,"FRK",'Mango Blocks - 13.06 - LONG'!$C:$C,$A14)/J14) -> NA | Q14: =IF(K14="NA","NA",SUM(L14:P14)) -> NA | R14: =COUNTIFS('Mango Blocks - 03.08 - LONG'!$E:$E,"<>NA",'Mango Blocks - 03.08 - LONG'!$E:$E,"<>OG",'Mango Blocks - 03.08 - LONG'!$E:$E,"<>-",'Mango Blocks - 03.08 - LONG'!$C:$C,$A14) -> 18 | S14: =IF(R14=0,"NA",COUNTIFS('Mango Blocks - 03.08 - LONG'!$E:$E,"H",'Mango Blocks - 03.08 - LONG'!$C:$C,$A14)) -> 18 | T14: =IF(R14=0,"NA",COUNTIFS('Mango Blocks - 03.08 - LONG'!$E:$E,T$2,'Mango Blocks - 03.08 - LONG'!$C:$C,$A14)/R14) -> 1 | U14: =IF(R14=0,"NA",COUNTIFS('Mango Blocks - 03.08 - LONG'!$E:$E,U$2,'Mango Blocks - 03.08 - LONG'!$C:$C,$A14)/R14) -> 0 | V14: =IF(R14=0,"NA",COUNTIFS('Mango Blocks - 03.08 - LONG'!$E:$E,V$2,'Mango Blocks - 03.08 - LONG'!$C:$C,$A14)/R14) -> 0 | W14: =IF(R14=0,"NA",COUNTIFS('Mango Blocks - 03.08 - LONG'!$E:$E,W$2,'Mango Blocks - 03.08 - LONG'!$C:$C,$A14)/R14) -> 0 | X14: =IF(R14=0,"NA",COUNTIFS('Mango Blocks - 03.08 - LONG'!$E:$E,X$2,'Mango Blocks - 03.08 - LONG'!$C:$C,$A14)/R14) -> 0 | Y14: =IF(S14="NA","NA",SUM(T14:X14)) -> 1 | Z14: =COUNTIFS('Mango Blocks - 27.08 - LONG'!$E:$E,"<>NA",'Mango Blocks - 27.08 - LONG'!$E:$E,"<>OG",'Mango Blocks - 27.08 - LONG'!$E:$E,"<>-",'Mango Blocks - 27.08 - LONG'!$C:$C,$A14) -> 0 | AA14: =IF(Z14=0,"NA",COUNTIFS('Mango Blocks - 27.08 - LONG'!$E:$E,"H",'Mango Blocks - 27.08 - LONG'!$C:$C,$A14)) -> NA | AB14: =IF(Z14=0,"NA",COUNTIFS('Mango Blocks - 27.08 - LONG'!$E:$E,AB$2,'Mango Blocks - 27.08 - LONG'!$C:$C,$A14)/Z14) -> NA | AC14: =IF(Z14=0,"NA",COUNTIFS('Mango Blocks - 27.08 - LONG'!$E:$E,AC$2,'Mango Blocks - 27.08 - LONG'!$C:$C,$A14)/Z14) -> NA | AD14: =IF(Z14=0,"NA",COUNTIFS('Mango Blocks - 27.08 - LONG'!$E:$E,AD$2,'Mango Blocks - 27.08 - LONG'!$C:$C,$A14)/Z14) -> NA | AE14: =IF(Z14=0,"NA",COUNTIFS('Mango Blocks - 27.08 - LONG'!$E:$E,AE$2,'Mango Blocks - 27.08 - LONG'!$C:$C,$A14)/Z14) -> NA | AF14: =IF(Z14=0,"NA",COUNTIFS('Mango Blocks - 27.08 - LONG'!$E:$E,AF$2,'Mango Blocks - 27.08 - LONG'!$C:$C,$A14)/Z14) -> NA | AG14: =IF(Z14=0,"NA",COUNTIFS('Mango Blocks - 27.08 - LONG'!$E:$E,AG$2,'Mango Blocks - 27.08 - LONG'!$C:$C,$A14)/Z14) -> NA | AH14: =IF(AA14="NA","NA",SUM(AB14:AF14)) -> NA
A15: Block2_Q3 | B15: =COUNTIFS('Mango Blocks - 09.05 - LONG'!$E:$E,"<>NA",'Mango Blocks - 09.05 - LONG'!$E:$E,"<>OG",'Mango Blocks - 09.05 - LONG'!$E:$E,"<>-",'Mango Blocks - 09.05 - LONG'!$C:$C,$A15) -> 0 | C15: =IF($B15=0,"NA",COUNTIFS('Mango Blocks - 09.05 - LONG'!$E:$E,"H",'Mango Blocks - 09.05 - LONG'!$C:$C,$A15)) -> NA | D15: =IF($B15=0,"NA",COUNTIFS('Mango Blocks - 09.05 - LONG'!$E:$E,"H",'Mango Blocks - 09.05 - LONG'!$C:$C,$A15)/B15) -> NA | E15: =IF($B15=0,"NA",COUNTIFS('Mango Blocks - 09.05 - LONG'!$E:$E,"PBL",'Mango Blocks - 09.05 - LONG'!$C:$C,$A15)/B15) -> NA | F15: =IF($B15=0,"NA",COUNTIFS('Mango Blocks - 09.05 - LONG'!$E:$E,"FBL",'Mango Blocks - 09.05 - LONG'!$C:$C,$A15)/B15) -> NA | G15: =IF($B15=0,"NA",COUNTIFS('Mango Blocks - 09.05 - LONG'!$E:$E,"PRK",'Mango Blocks - 09.05 - LONG'!$C:$C,$A15)/B15) -> NA | H15: =IF($B15=0,"NA",COUNTIFS('Mango Blocks - 09.05 - LONG'!$E:$E,"FRK",'Mango Blocks - 09.05 - LONG'!$C:$C,$A15)/B15) -> NA | I15: =IF(C15="NA","NA",SUM(D15:H15)) -> NA | J15: =COUNTIFS('Mango Blocks - 13.06 - LONG'!$E:$E,"<>NA",'Mango Blocks - 13.06 - LONG'!$E:$E,"<>OG",'Mango Blocks - 13.06 - LONG'!$E:$E,"<>-",'Mango Blocks - 13.06 - LONG'!$C:$C,$A15) -> 0 | K15: =IF(J15=0,"NA",COUNTIFS('Mango Blocks - 13.06 - LONG'!$E:$E,"H",'Mango Blocks - 13.06 - LONG'!$C:$C,$A15)) -> NA | L15: =IF(J15=0,"NA",COUNTIFS('Mango Blocks - 13.06 - LONG'!$E:$E,"H",'Mango Blocks - 13.06 - LONG'!$C:$C,$A15)/J15) -> NA | M15: =IF(J15=0,"NA",COUNTIFS('Mango Blocks - 13.06 - LONG'!$E:$E,"PBL",'Mango Blocks - 13.06 - LONG'!$C:$C,$A15)/J15) -> NA | N15: =IF(J15=0,"NA",COUNTIFS('Mango Blocks - 13.06 - LONG'!$E:$E,"FBL",'Mango Blocks - 13.06 - LONG'!$C:$C,$A15)/J15) -> NA | O15: =IF(J15=0,"NA",COUNTIFS('Mango Blocks - 13.06 - LONG'!$E:$E,"PRK",'Mango Blocks - 13.06 - LONG'!$C:$C,$A15)/J15) -> NA | P15: =IF(J15=0,"NA",COUNTIFS('Mango Blocks - 13.06 - LONG'!$E:$E,"FRK",'Mango Blocks - 13.06 - LONG'!$C:$C,$A15)/J15) -> NA | Q15: =IF(K15="NA","NA",SUM(L15:P15)) -> NA | R15: =COUNTIFS('Mango Blocks - 03.08 - LONG'!$E:$E,"<>NA",'Mango Blocks - 03.08 - LONG'!$E:$E,"<>OG",'Mango Blocks - 03.08 - LONG'!$E:$E,"<>-",'Mango Blocks - 03.08 - LONG'!$C:$C,$A15) -> 4 | S15: =IF(R15=0,"NA",COUNTIFS('Mango Blocks - 03.08 - LONG'!$E:$E,"H",'Mango Blocks - 03.08 - LONG'!$C:$C,$A15)) -> 0 | T15: =IF(R15=0,"NA",COUNTIFS('Mango Blocks - 03.08 - LONG'!$E:$E,T$2,'Mango Blocks - 03.08 - LONG'!$C:$C,$A15)/R15) -> 0 | U15: =IF(R15=0,"NA",COUNTIFS('Mango Blocks - 03.08 - LONG'!$E:$E,U$2,'Mango Blocks - 03.08 - LONG'!$C:$C,$A15)/R15) -> 1 | V15: =IF(R15=0,"NA",COUNTIFS('Mango Blocks - 03.08 - LONG'!$E:$E,V$2,'Mango Blocks - 03.08 - LONG'!$C:$C,$A15)/R15) -> 0 | W15: =IF(R15=0,"NA",COUNTIFS('Mango Blocks - 03.08 - LONG'!$E:$E,W$2,'Mango Blocks - 03.08 - LONG'!$C:$C,$A15)/R15) -> 0 | X15: =IF(R15=0,"NA",COUNTIFS('Mango Blocks - 03.08 - LONG'!$E:$E,X$2,'Mango Blocks - 03.08 - LONG'!$C:$C,$A15)/R15) -> 0 | Y15: =IF(S15="NA","NA",SUM(T15:X15)) -> 1 | Z15: =COUNTIFS('Mango Blocks - 27.08 - LONG'!$E:$E,"<>NA",'Mango Blocks - 27.08 - LONG'!$E:$E,"<>OG",'Mango Blocks - 27.08 - LONG'!$E:$E,"<>-",'Mango Blocks - 27.08 - LONG'!$C:$C,$A15) -> 0 | AA15: =IF(Z15=0,"NA",COUNTIFS('Mango Blocks - 27.08 - LONG'!$E:$E,"H",'Mango Blocks - 27.08 - LONG'!$C:$C,$A15)) -> NA | AB15: =IF(Z15=0,"NA",COUNTIFS('Mango Blocks - 27.08 - LONG'!$E:$E,AB$2,'Mango Blocks - 27.08 - LONG'!$C:$C,$A15)/Z15) -> NA | AC15: =IF(Z15=0,"NA",COUNTIFS('Mango Blocks - 27.08 - LONG'!$E:$E,AC$2,'Mango Blocks - 27.08 - LONG'!$C:$C,$A15)/Z15) -> NA | AD15: =IF(Z15=0,"NA",COUNTIFS('Mango Blocks - 27.08 - LONG'!$E:$E,AD$2,'Mango Blocks - 27.08 - LONG'!$C:$C,$A15)/Z15) -> NA | AE15: =IF(Z15=0,"NA",COUNTIFS('Mango Blocks - 27.08 - LONG'!$E:$E,AE$2,'Mango Blocks - 27.08 - LONG'!$C:$C,$A15)/Z15) -> NA | AF15: =IF(Z15=0,"NA",COUNTIFS('Mango Blocks - 27.08 - LONG'!$E:$E,AF$2,'Mango Blocks - 27.08 - LONG'!$C:$C,$A15)/Z15) -> NA | AG15: =IF(Z15=0,"NA",COUNTIFS('Mango Blocks - 27.08 - LONG'!$E:$E,AG$2,'Mango Blocks - 27.08 - LONG'!$C:$C,$A15)/Z15) -> NA | AH15: =IF(AA15="NA","NA",SUM(AB15:AF15)) -> NA
A16: Block2_Q4 | B16: =COUNTIFS('Mango Blocks - 09.05 - LONG'!$E:$E,"<>NA",'Mango Blocks - 09.05 - LONG'!$E:$E,"<>OG",'Mango Blocks - 09.05 - LONG'!$E:$E,"<>-",'Mango Blocks - 09.05 - LONG'!$C:$C,$A16) -> 17 | C16: =IF($B16=0,"NA",COUNTIFS('Mango Blocks - 09.05 - LONG'!$E:$E,"H",'Mango Blocks - 09.05 - LONG'!$C:$C,$A16)) -> 13 | D16: =IF($B16=0,"NA",COUNTIFS('Mango Blocks - 09.05 - LONG'!$E:$E,"H",'Mango Blocks - 09.05 - LONG'!$C:$C,$A16)/B16) -> 0.76470588 | E16: =IF($B16=0,"NA",COUNTIFS('Mango Blocks - 09.05 - LONG'!$E:$E,"PBL",'Mango Blocks - 09.05 - LONG'!$C:$C,$A16)/B16) -> 0.058823529 | F16: =IF($B16=0,"NA",COUNTIFS('Mango Blocks - 09.05 - LONG'!$E:$E,"FBL",'Mango Blocks - 09.05 - LONG'!$C:$C,$A16)/B16) -> 0 | G16: =IF($B16=0,"NA",COUNTIFS('Mango Blocks - 09.05 - LONG'!$E:$E,"PRK",'Mango Blocks - 09.05 - LONG'!$C:$C,$A16)/B16) -> 0.17647059 | H16: =IF($B16=0,"NA",COUNTIFS('Mango Blocks - 09.05 - LONG'!$E:$E,"FRK",'Mango Blocks - 09.05 - LONG'!$C:$C,$A16)/B16) -> 0 | I16: =IF(C16="NA","NA",SUM(D16:H16)) -> 1 | J16: =COUNTIFS('Mango Blocks - 13.06 - LONG'!$E:$E,"<>NA",'Mango Blocks - 13.06 - LONG'!$E:$E,"<>OG",'Mango Blocks - 13.06 - LONG'!$E:$E,"<>-",'Mango Blocks - 13.06 - LONG'!$C:$C,$A16) -> 0 | K16: =IF(J16=0,"NA",COUNTIFS('Mango Blocks - 13.06 - LONG'!$E:$E,"H",'Mango Blocks - 13.06 - LONG'!$C:$C,$A16)) -> NA | L16: =IF(J16=0,"NA",COUNTIFS('Mango Blocks - 13.06 - LONG'!$E:$E,"H",'Mango Blocks - 13.06 - LONG'!$C:$C,$A16)/J16) -> NA | M16: =IF(J16=0,"NA",COUNTIFS('Mango Blocks - 13.06 - LONG'!$E:$E,"PBL",'Mango Blocks - 13.06 - LONG'!$C:$C,$A16)/J16) -> NA | N16: =IF(J16=0,"NA",COUNTIFS('Mango Blocks - 13.06 - LONG'!$E:$E,"FBL",'Mango Blocks - 13.06 - LONG'!$C:$C,$A16)/J16) -> NA | O16: =IF(J16=0,"NA",COUNTIFS('Mango Blocks - 13.06 - LONG'!$E:$E,"PRK",'Mango Blocks - 13.06 - LONG'!$C:$C,$A16)/J16) -> NA | P16: =IF(J16=0,"NA",COUNTIFS('Mango Blocks - 13.06 - LONG'!$E:$E,"FRK",'Mango Blocks - 13.06 - LONG'!$C:$C,$A16)/J16) -> NA | Q16: =IF(K16="NA","NA",SUM(L16:P16)) -> NA | R16: =COUNTIFS('Mango Blocks - 03.08 - LONG'!$E:$E,"<>NA",'Mango Blocks - 03.08 - LONG'!$E:$E,"<>OG",'Mango Blocks - 03.08 - LONG'!$E:$E,"<>-",'Mango Blocks - 03.08 - LONG'!$C:$C,$A16) -> 0 | S16: =IF(R16=0,"NA",COUNTIFS('Mango Blocks - 03.08 - LONG'!$E:$E,"H",'Mango Blocks - 03.08 - LONG'!$C:$C,$A16)) -> NA | T16: =IF(R16=0,"NA",COUNTIFS('Mango Blocks - 03.08 - LONG'!$E:$E,T$2,'Mango Blocks - 03.08 - LONG'!$C:$C,$A16)/R16) -> NA | U16: =IF(R16=0,"NA",COUNTIFS('Mango Blocks - 03.08 - LONG'!$E:$E,U$2,'Mango Blocks - 03.08 - LONG'!$C:$C,$A16)/R16) -> NA | V16: =IF(R16=0,"NA",COUNTIFS('Mango Blocks - 03.08 - LONG'!$E:$E,V$2,'Mango Blocks - 03.08 - LONG'!$C:$C,$A16)/R16) -> NA | W16: =IF(R16=0,"NA",COUNTIFS('Mango Blocks - 03.08 - LONG'!$E:$E,W$2,'Mango Blocks - 03.08 - LONG'!$C:$C,$A16)/R16) -> NA | X16: =IF(R16=0,"NA",COUNTIFS('Mango Blocks - 03.08 - LONG'!$E:$E,X$2,'Mango Blocks - 03.08 - LONG'!$C:$C,$A16)/R16) -> NA | Y16: =IF(S16="NA","NA",SUM(T16:X16)) -> NA | Z16: =COUNTIFS('Mango Blocks - 27.08 - LONG'!$E:$E,"<>NA",'Mango Blocks - 27.08 - LONG'!$E:$E,"<>OG",'Mango Blocks - 27.08 - LONG'!$E:$E,"<>-",'Mango Blocks - 27.08 - LONG'!$C:$C,$A16) -> 0 | AA16: =IF(Z16=0,"NA",COUNTIFS('Mango Blocks - 27.08 - LONG'!$E:$E,"H",'Mango Blocks - 27.08 - LONG'!$C:$C,$A16)) -> NA | AB16: =IF(Z16=0,"NA",COUNTIFS('Mango Blocks - 27.08 - LONG'!$E:$E,AB$2,'Mango Blocks - 27.08 - LONG'!$C:$C,$A16)/Z16) -> NA | AC16: =IF(Z16=0,"NA",COUNTIFS('Mango Blocks - 27.08 - LONG'!$E:$E,AC$2,'Mango Blocks - 27.08 - LONG'!$C:$C,$A16)/Z16) -> NA | AD16: =IF(Z16=0,"NA",COUNTIFS('Mango Blocks - 27.08 - LONG'!$E:$E,AD$2,'Mango Blocks - 27.08 - LONG'!$C:$C,$A16)/Z16) -> NA | AE16: =IF(Z16=0,"NA",COUNTIFS('Mango Blocks - 27.08 - LONG'!$E:$E,AE$2,'Mango Blocks - 27.08 - LONG'!$C:$C,$A16)/Z16) -> NA | AF16: =IF(Z16=0,"NA",COUNTIFS('Mango Blocks - 27.08 - LONG'!$E:$E,AF$2,'Mango Blocks - 27.08 - LONG'!$C:$C,$A16)/Z16) -> NA | AG16: =IF(Z16=0,"NA",COUNTIFS('Mango Blocks - 27.08 - LONG'!$E:$E,AG$2,'Mango Blocks - 27.08 - LONG'!$C:$C,$A16)/Z16) -> NA | AH16: =IF(AA16="NA","NA",SUM(AB16:AF16)) -> NA
